Workbook

Sheet Summarize
B2: Results for C_k = \bar{C}_k | S2: Compared with BBR | AE2: Compared with BBR, B&B | AO2: Impact of Cuts
B3: Struct. | C3: OS | D3: TD | E3: Configuration K=2 | I3: Configuration K=3 | M3: Configuration K=4 | S3: Struct. | T3: OS | U3: TD | V3: opt BPC | W3: opt BBR | X3: gap BPC | Y3: gap BBR | Z3: time BPC | AA3: time BBR | AE3: ='Classical benchmark'!G3 -> Instances | AF3: ='Classical benchmark'!H3 -> n | AG3: ='Classical benchmark'!J3 -> #I | AH3: ='Classical benchmark'!K3 -> time BPC | AI3: opt BPC | AJ3: ='Classical benchmark'!L3 -> time BBR | AK3: opt BBR | AL3: ='Classical benchmark'!M3 -> time B&B | AM3: ='Classical benchmark'!N3 -> opt B&B | AP3: BPC | AQ3: no CP | AR3: no config | AS3: BP
E4: opt | F4: gap(\%) | G4: total time | I4: opt | J4: gap(\%) | K4: total time | M4: opt | N4: gap(\%) | O4: total time | S4: BN | T4: 0.2 | U4: BM | V4: ='Otto benchmark'!X3 -> 25 | W4: ='Otto benchmark'!Y3 -> 25 | X4: ='Otto benchmark'!Z3 -> 0 | Y4: ='Otto benchmark'!AA3 -> 0 | Z4: ='Otto benchmark'!AB3 -> 0.59472 | AA4: ='Otto benchmark'!AC3 -> 7.92 | AE4: ='Classical benchmark'!G4 -> Arcus1 | AF4: ='Classical benchmark'!H4 -> 83 | AG4: ='Classical benchmark'!J4 -> 16 | AH4: ='Classical benchmark'!K4 -> 0.0289375 | AI4: 16 | AJ4: ='Classical benchmark'!L4 -> 0.22 | AK4: 16 | AL4: ='Classical benchmark'!M4 -> 5.69 | AM4: ='Classical benchmark'!N4 -> 16 | AO4: time | AP4: ='cutting planes'!AI3 -> 2500.5502 | AQ4: ='cutting planes'!AI4 -> 2714.8443 | AR4: ='cutting planes'!AI5 -> 2573.5978 | AS4: ='cutting planes'!AI6 -> 2871.5063
B5: BN | C5: 0.2 | D5: BM | E5: ='C_k = bar{C}_k'!X2 -> 25 | F5: ='C_k = bar{C}_k'!Y2 -> 0 | G5: ='C_k = bar{C}_k'!$Z$2 -> 0.65036 | I5: ='C_k = bar{C}_k'!X3 -> 25 | J5: ='C_k = bar{C}_k'!Y3 -> 0 | K5: ='C_k = bar{C}_k'!$Z$3 -> 0.66044 | M5: ='C_k = bar{C}_k'!X4 -> 25 | N5: ='C_k = bar{C}_k'!Y4 -> 0 | O5: ='C_k = bar{C}_k'!$Z$4 -> 0.7016 | U5: PB | V5: ='Otto benchmark'!X4 -> 25 | W5: ='Otto benchmark'!Y4 -> 25 | X5: ='Otto benchmark'!Z4 -> 0 | Y5: ='Otto benchmark'!AA4 -> 0 | Z5: ='Otto benchmark'!AB4 -> 0.35476 | AA5: ='Otto benchmark'!AC4 -> 7.54 | AE5: ='Classical benchmark'!G5 -> Arcus2 | AF5: ='Classical benchmark'!H5 -> 111 | AG5: ='Classical benchmark'!J5 -> 17 | AH5: ='Classical benchmark'!K5 -> 0.43141176 | AI5: 17 | AJ5: ='Classical benchmark'!L5 -> 7.14 | AK5: 17 | AL5: ='Classical benchmark'!M5 -> 211.49 | AM5: ='Classical benchmark'!N5 -> 17 | AO5: opt | AP5: =CONCATENATE(TEXT('cutting planes'!AG3, "0"),"/",TEXT('cutting planes'!AJ3, "0")) -> 28/76 | AQ5: =CONCATENATE(TEXT('cutting planes'!AG4, "0"),"/",TEXT('cutting planes'!AJ3, "0")) -> 21/76 | AR5: =CONCATENATE(TEXT('cutting planes'!AG5, "0"),"/",TEXT('cutting planes'!AJ3, "0")) -> 25/76 | AS5: =CONCATENATE(TEXT('cutting planes'!AG6, "0"),"/",TEXT('cutting planes'!AJ3, "0")) -> 17/76
D6: PB | E6: ='C_k = bar{C}_k'!X5 -> 25 | F6: ='C_k = bar{C}_k'!Y5 -> 0 | G6: ='C_k = bar{C}_k'!$Z$5 -> 0.59804 | I6: ='C_k = bar{C}_k'!X6 -> 25 | J6: ='C_k = bar{C}_k'!Y6 -> 0 | K6: ='C_k = bar{C}_k'!$Z$6 -> 0.66828 | M6: ='C_k = bar{C}_k'!X7 -> 24 | N6: ='C_k = bar{C}_k'!Y7 -> 0.28571429 | O6: ='C_k = bar{C}_k'!$Z$7 -> 181.76604 | U6: PM | V6: ='Otto benchmark'!X5 -> 23 | W6: ='Otto benchmark'!Y5 -> 16 | X6: ='Otto benchmark'!Z5 -> 0.15686275 | Y6: ='Otto benchmark'!AA5 -> 0.74 | Z6: ='Otto benchmark'!AB5 -> 293.12908 | AA6: ='Otto benchmark'!AC5 -> 2768.85 | AE6: ='Classical benchmark'!G6 -> Barthold | AF6: ='Classical benchmark'!H6 -> 148 | AG6: ='Classical benchmark'!J6 -> 8 | AH6: ='Classical benchmark'!K6 -> 0.526125 | AI6: 8 | AJ6: ='Classical benchmark'!L6 -> 90.66 | AK6: 8 | AL6: ='Classical benchmark'!M6 -> 4.41 | AM6: ='Classical benchmark'!N6 -> 8 | AO6: gap | AP6: ='cutting planes'!AH3 -> 1.6045444 | AQ6: ='cutting planes'!AH4 -> 1.7354743 | AR6: ='cutting planes'!AH5 -> 1.6160655 | AS6: ='cutting planes'!AH6 -> 1.8939168
D7: PM | E7: ='C_k = bar{C}_k'!X8 -> 22 | F7: ='C_k = bar{C}_k'!Y8 -> 0.23378582 | G7: ='C_k = bar{C}_k'!$Z$8 -> 454.1422 | I7: ='C_k = bar{C}_k'!X9 -> 23 | J7: ='C_k = bar{C}_k'!Y9 -> 0.15535445 | K7: ='C_k = bar{C}_k'!$Z$9 -> 365.99952 | M7: ='C_k = bar{C}_k'!X10 -> 24 | N7: ='C_k = bar{C}_k'!Y10 -> 0.078431373 | O7: ='C_k = bar{C}_k'!$Z$10 -> 212.07732 | T7: 0.6 | U7: BM | V7: ='Otto benchmark'!X6 -> 24 | W7: ='Otto benchmark'!Y6 -> 25 | X7: ='Otto benchmark'!Z6 -> 0.18181818 | Y7: ='Otto benchmark'!AA6 -> 0 | Z7: ='Otto benchmark'!AB6 -> 144.86004 | AA7: ='Otto benchmark'!AC6 -> 29.72 | AE7: ='Classical benchmark'!G7 -> Barthold2 | AF7: ='Classical benchmark'!H7 -> 148 | AG7: ='Classical benchmark'!J7 -> 27 | AH7: ='Classical benchmark'!K7 -> 2.4512222 | AI7: 27 | AJ7: ='Classical benchmark'!L7 -> 29.66 | AK7: 27 | AL7: ='Classical benchmark'!M7 -> 575.35 | AM7: ='Classical benchmark'!N7 -> 25
C8: 0.6 | D8: BM | E8: ='C_k = bar{C}_k'!X11 -> 24 | F8: ='C_k = bar{C}_k'!Y11 -> 0.18181818 | G8: ='C_k = bar{C}_k'!$Z$11 -> 144.93832 | I8: ='C_k = bar{C}_k'!X12 -> 23 | J8: ='C_k = bar{C}_k'!Y12 -> 0.36363636 | K8: ='C_k = bar{C}_k'!$Z$12 -> 289.11676 | M8: ='C_k = bar{C}_k'!X13 -> 22 | N8: ='C_k = bar{C}_k'!Y13 -> 0.70301357 | O8: ='C_k = bar{C}_k'!$Z$13 -> 433.0632 | U8: PB | V8: ='Otto benchmark'!X7 -> 25 | W8: ='Otto benchmark'!Y7 -> 25 | X8: ='Otto benchmark'!Z7 -> 0 | Y8: ='Otto benchmark'!AA7 -> 0 | Z8: ='Otto benchmark'!AB7 -> 0.13908 | AA8: ='Otto benchmark'!AC7 -> 2.29 | AE8: ='Classical benchmark'!G8 -> Bowman | AF8: ='Classical benchmark'!H8 -> 8 | AG8: ='Classical benchmark'!J8 -> 1 | AH8: ='Classical benchmark'!K8 -> 0.001 | AI8: 1 | AJ8: ='Classical benchmark'!L8 -> 0 | AK8: 1 | AL8: ='Classical benchmark'!M8 -> 0.05 | AM8: ='Classical benchmark'!N8 -> 1
D9: PB | E9: ='C_k = bar{C}_k'!X14 -> 25 | F9: ='C_k = bar{C}_k'!Y14 -> 0 | G9: ='C_k = bar{C}_k'!$Z$14 -> 0.62592 | I9: ='C_k = bar{C}_k'!X15 -> 25 | J9: ='C_k = bar{C}_k'!Y15 -> 0 | K9: ='C_k = bar{C}_k'!$Z$15 -> 1.08844 | M9: ='C_k = bar{C}_k'!X16 -> 25 | N9: ='C_k = bar{C}_k'!Y16 -> 0 | O9: ='C_k = bar{C}_k'!$Z$16 -> 2.58244 | U9: PM | V9: ='Otto benchmark'!X8 -> 24 | W9: ='Otto benchmark'!Y8 -> 25 | X9: ='Otto benchmark'!Z8 -> 0.078431373 | Y9: ='Otto benchmark'!AA8 -> 0 | Z9: ='Otto benchmark'!AB8 -> 145.64512 | AA9: ='Otto benchmark'!AC8 -> 68.38 | AE9: ='Classical benchmark'!G9 -> Buxey | AF9: ='Classical benchmark'!H9 -> 29 | AG9: ='Classical benchmark'!J9 -> 7 | AH9: ='Classical benchmark'!K9 -> 0.0018571429 | AI9: 7 | AJ9: ='Classical benchmark'!L9 -> 0.03 | AK9: 7 | AL9: ='Classical benchmark'!M9 -> 171.94 | AM9: ='Classical benchmark'!N9 -> 7
D10: PM | E10: ='C_k = bar{C}_k'!X17 -> 23 | F10: ='C_k = bar{C}_k'!Y17 -> 0.15535445 | G10: ='C_k = bar{C}_k'!$Z$17 -> 294.73324 | I10: ='C_k = bar{C}_k'!X18 -> 23 | J10: ='C_k = bar{C}_k'!Y18 -> 0.15250545 | K10: ='C_k = bar{C}_k'!$Z$18 -> 290.92688 | M10: ='C_k = bar{C}_k'!X19 -> 23 | N10: ='C_k = bar{C}_k'!Y19 -> 0.15115865 | O10: ='C_k = bar{C}_k'!$Z$19 -> 313.05228 | S10: CH | T10: 0.2 | U10: BM | V10: ='Otto benchmark'!X9 -> 25 | W10: ='Otto benchmark'!Y9 -> 25 | X10: ='Otto benchmark'!Z9 -> 0 | Y10: ='Otto benchmark'!AA9 -> 0 | Z10: ='Otto benchmark'!AB9 -> 0.69992 | AA10: ='Otto benchmark'!AC9 -> 5.09 | AE10: ='Classical benchmark'!G10 -> Gunther | AF10: ='Classical benchmark'!H10 -> 35 | AG10: ='Classical benchmark'!J10 -> 7 | AH10: ='Classical benchmark'!K10 -> 0.0012857143 | AI10: 7 | AJ10: ='Classical benchmark'!L10 -> 0 | AK10: 7 | AL10: ='Classical benchmark'!M10 -> 114.83 | AM10: ='Classical benchmark'!N10 -> 7
B11: CH | C11: 0.2 | D11: BM | E11: ='C_k = bar{C}_k'!X20 -> 25 | F11: ='C_k = bar{C}_k'!Y20 -> 0 | G11: ='C_k = bar{C}_k'!$Z$20 -> 0.7608 | I11: ='C_k = bar{C}_k'!X21 -> 25 | J11: ='C_k = bar{C}_k'!Y21 -> 0 | K11: ='C_k = bar{C}_k'!$Z$21 -> 0.76668 | M11: ='C_k = bar{C}_k'!X22 -> 25 | N11: ='C_k = bar{C}_k'!Y22 -> 0 | O11: ='C_k = bar{C}_k'!$Z$22 -> 0.77732 | U11: PB | V11: ='Otto benchmark'!X10 -> 25 | W11: ='Otto benchmark'!Y10 -> 25 | X11: ='Otto benchmark'!Z10 -> 0 | Y11: ='Otto benchmark'!AA10 -> 0 | Z11: ='Otto benchmark'!AB10 -> 0.27628 | AA11: ='Otto benchmark'!AC10 -> 5.42 | AE11: ='Classical benchmark'!G11 -> Hahn | AF11: ='Classical benchmark'!H11 -> 53 | AG11: ='Classical benchmark'!J11 -> 5 | AH11: ='Classical benchmark'!K11 -> 0.006 | AI11: 5 | AJ11: ='Classical benchmark'!L11 -> 0.02 | AK11: 5 | AL11: ='Classical benchmark'!M11 -> 0.22 | AM11: ='Classical benchmark'!N11 -> 5
D12: PB | E12: ='C_k = bar{C}_k'!X23 -> 25 | F12: ='C_k = bar{C}_k'!Y23 -> 0 | G12: ='C_k = bar{C}_k'!$Z$23 -> 0.39288 | I12: ='C_k = bar{C}_k'!X24 -> 25 | J12: ='C_k = bar{C}_k'!Y24 -> 0 | K12: ='C_k = bar{C}_k'!$Z$24 -> 0.48804 | M12: ='C_k = bar{C}_k'!X25 -> 25 | N12: ='C_k = bar{C}_k'!Y25 -> 0 | O12: ='C_k = bar{C}_k'!$Z$25 -> 43.50984 | U12: PM | V12: ='Otto benchmark'!X11 -> 23 | W12: ='Otto benchmark'!Y11 -> 18 | X12: ='Otto benchmark'!Z11 -> 0.15843137 | Y12: ='Otto benchmark'!AA11 -> 0.54 | Z12: ='Otto benchmark'!AB11 -> 305.39436 | AA12: ='Otto benchmark'!AC11 -> 2582.75 | AE12: ='Classical benchmark'!G12 -> Heskiaoff | AF12: ='Classical benchmark'!H12 -> 28 | AG12: ='Classical benchmark'!J12 -> 6 | AH12: ='Classical benchmark'!K12 -> 0.0013333333 | AI12: 6 | AJ12: ='Classical benchmark'!L12 -> 0.05 | AK12: 6 | AL12: ='Classical benchmark'!M12 -> 0.22 | AM12: ='Classical benchmark'!N12 -> 6
D13: PM | E13: ='C_k = bar{C}_k'!X26 -> 20 | F13: ='C_k = bar{C}_k'!Y26 -> 0.39541848 | G13: ='C_k = bar{C}_k'!$Z$26 -> 726.75252 | I13: ='C_k = bar{C}_k'!X27 -> 21 | J13: ='C_k = bar{C}_k'!Y27 -> 0.3184954 | K13: ='C_k = bar{C}_k'!$Z$27 -> 609.025 | M13: ='C_k = bar{C}_k'!X28 -> 20 | N13: ='C_k = bar{C}_k'!Y28 -> 0.38992397 | O13: ='C_k = bar{C}_k'!$Z$28 -> 753.7788 | T13: 0.6 | U13: BM | V13: ='Otto benchmark'!X12 -> 25 | W13: ='Otto benchmark'!Y12 -> 25 | X13: ='Otto benchmark'!Z12 -> 0 | Y13: ='Otto benchmark'!AA12 -> 0 | Z13: ='Otto benchmark'!AB12 -> 0.6276 | AA13: ='Otto benchmark'!AC12 -> 1.39 | AE13: ='Classical benchmark'!G13 -> Jackson | AF13: ='Classical benchmark'!H13 -> 11 | AG13: ='Classical benchmark'!J13 -> 6 | AH13: ='Classical benchmark'!K13 -> 0.001 | AI13: 6 | AJ13: ='Classical benchmark'!L13 -> 0 | AK13: 6 | AL13: ='Classical benchmark'!M13 -> 0.06 | AM13: ='Classical benchmark'!N13 -> 6
C14: 0.6 | D14: BM | E14: ='C_k = bar{C}_k'!X29 -> 25 | F14: ='C_k = bar{C}_k'!Y29 -> 0 | G14: ='C_k = bar{C}_k'!$Z$29 -> 0.93088 | I14: ='C_k = bar{C}_k'!X30 -> 24 | J14: ='C_k = bar{C}_k'!Y30 -> 0.14814815 | K14: ='C_k = bar{C}_k'!$Z$30 -> 145.10664 | M14: ='C_k = bar{C}_k'!X31 -> 25 | N14: ='C_k = bar{C}_k'!Y31 -> 0 | O14: ='C_k = bar{C}_k'!$Z$31 -> 1.39552 | U14: PB | V14: ='Otto benchmark'!X13 -> 25 | W14: ='Otto benchmark'!Y13 -> 25 | X14: ='Otto benchmark'!Z13 -> 0 | Y14: ='Otto benchmark'!AA13 -> 0 | Z14: ='Otto benchmark'!AB13 -> 0.09524 | AA14: ='Otto benchmark'!AC13 -> 0.52 | AE14: ='Classical benchmark'!G14 -> Jaeschke | AF14: ='Classical benchmark'!H14 -> 9 | AG14: ='Classical benchmark'!J14 -> 5 | AH14: ='Classical benchmark'!K14 -> 0.001 | AI14: 5 | AJ14: ='Classical benchmark'!L14 -> 0 | AK14: 5 | AL14: ='Classical benchmark'!M14 -> 0.03 | AM14: ='Classical benchmark'!N14 -> 5
D15: PB | E15: ='C_k = bar{C}_k'!X32 -> 25 | F15: ='C_k = bar{C}_k'!Y32 -> 0 | G15: ='C_k = bar{C}_k'!$Z$32 -> 0.36772 | I15: ='C_k = bar{C}_k'!X33 -> 25 | J15: ='C_k = bar{C}_k'!Y33 -> 0 | K15: ='C_k = bar{C}_k'!$Z$33 -> 1.01336 | M15: ='C_k = bar{C}_k'!X34 -> 25 | N15: ='C_k = bar{C}_k'!Y34 -> 0 | O15: ='C_k = bar{C}_k'!$Z$34 -> 1.1456 | U15: PM | V15: ='Otto benchmark'!X14 -> 24 | W15: ='Otto benchmark'!Y14 -> 25 | X15: ='Otto benchmark'!Z14 -> 0.068965517 | Y15: ='Otto benchmark'!AA14 -> 0 | Z15: ='Otto benchmark'!AB14 -> 145.825 | AA15: ='Otto benchmark'!AC14 -> 34.83 | AE15: ='Classical benchmark'!G15 -> Kilbridge | AF15: ='Classical benchmark'!H15 -> 45 | AG15: ='Classical benchmark'!J15 -> 10 | AH15: ='Classical benchmark'!K15 -> 0.0052 | AI15: 10 | AJ15: ='Classical benchmark'!L15 -> 0.04 | AK15: 10 | AL15: ='Classical benchmark'!M15 -> 0.58 | AM15: ='Classical benchmark'!N15 -> 10
D16: PM | E16: ='C_k = bar{C}_k'!X35 -> 24 | F16: ='C_k = bar{C}_k'!Y35 -> 0.071428571 | G16: ='C_k = bar{C}_k'!$Z$35 -> 147.00044 | I16: ='C_k = bar{C}_k'!X36 -> 23 | J16: ='C_k = bar{C}_k'!Y36 -> 0.14039409 | K16: ='C_k = bar{C}_k'!$Z$36 -> 290.55428 | M16: ='C_k = bar{C}_k'!X37 -> 24 | N16: ='C_k = bar{C}_k'!Y37 -> 0.068965517 | O16: ='C_k = bar{C}_k'!$Z$37 -> 148.23668 | S16: MIXED | T16: 0.2 | U16: BM | V16: ='Otto benchmark'!X15 -> 25 | W16: ='Otto benchmark'!Y15 -> 25 | X16: ='Otto benchmark'!Z15 -> 0 | Y16: ='Otto benchmark'!AA15 -> 0 | Z16: ='Otto benchmark'!AB15 -> 0.78948 | AA16: ='Otto benchmark'!AC15 -> 9.08 | AE16: ='Classical benchmark'!G16 -> Lutz1 | AF16: ='Classical benchmark'!H16 -> 32 | AG16: ='Classical benchmark'!J16 -> 6 | AH16: ='Classical benchmark'!K16 -> 0.0018333333 | AI16: 6 | AJ16: ='Classical benchmark'!L16 -> 0 | AK16: 6 | AL16: ='Classical benchmark'!M16 -> 0.13 | AM16: ='Classical benchmark'!N16 -> 6
B17: MIXED | C17: 0.2 | D17: BM | E17: ='C_k = bar{C}_k'!X38 -> 25 | F17: ='C_k = bar{C}_k'!Y38 -> 0 | G17: ='C_k = bar{C}_k'!$Z$38 -> 0.79532 | I17: ='C_k = bar{C}_k'!X39 -> 25 | J17: ='C_k = bar{C}_k'!Y39 -> 0 | K17: ='C_k = bar{C}_k'!$Z$39 -> 0.73324 | M17: ='C_k = bar{C}_k'!X40 -> 25 | N17: ='C_k = bar{C}_k'!Y40 -> 0 | O17: ='C_k = bar{C}_k'!$Z$40 -> 0.71892 | U17: PB | V17: ='Otto benchmark'!X16 -> 25 | W17: ='Otto benchmark'!Y16 -> 25 | X17: ='Otto benchmark'!Z16 -> 0 | Y17: ='Otto benchmark'!AA16 -> 0 | Z17: ='Otto benchmark'!AB16 -> 0.443 | AA17: ='Otto benchmark'!AC16 -> 6.64 | AE17: ='Classical benchmark'!G17 -> Lutz2 | AF17: ='Classical benchmark'!H17 -> 89 | AG17: ='Classical benchmark'!J17 -> 11 | AH17: ='Classical benchmark'!K17 -> 0.32118182 | AI17: 11 | AJ17: ='Classical benchmark'!L17 -> 0.22 | AK17: 11 | AL17: ='Classical benchmark'!M17 -> 106.99 | AM17: ='Classical benchmark'!N17 -> 11
D18: PB | E18: ='C_k = bar{C}_k'!X41 -> 25 | F18: ='C_k = bar{C}_k'!Y41 -> 0 | G18: ='C_k = bar{C}_k'!$Z$41 -> 0.76884 | I18: ='C_k = bar{C}_k'!X42 -> 25 | J18: ='C_k = bar{C}_k'!Y42 -> 0 | K18: ='C_k = bar{C}_k'!$Z$42 -> 0.74652 | M18: ='C_k = bar{C}_k'!X43 -> 25 | N18: ='C_k = bar{C}_k'!Y43 -> 0 | O18: ='C_k = bar{C}_k'!$Z$43 -> 10.10616 | U18: PM | V18: ='Otto benchmark'!X17 -> 25 | W18: ='Otto benchmark'!Y17 -> 18 | X18: ='Otto benchmark'!Z17 -> 0 | Y18: ='Otto benchmark'!AA17 -> 0.66 | Z18: ='Otto benchmark'!AB17 -> 18.3946 | AA18: ='Otto benchmark'!AC17 -> 2312.61 | AE18: ='Classical benchmark'!G18 -> Lutz3 | AF18: ='Classical benchmark'!H18 -> 89 | AG18: ='Classical benchmark'!J18 -> 12 | AH18: ='Classical benchmark'!K18 -> 0.018916667 | AI18: 12 | AJ18: ='Classical benchmark'!L18 -> 0.03 | AK18: 12 | AL18: ='Classical benchmark'!M18 -> 1.66 | AM18: ='Classical benchmark'!N18 -> 12
D19: PM | E19: ='C_k = bar{C}_k'!X44 -> 23 | F19: ='C_k = bar{C}_k'!Y44 -> 0.15407407 | G19: ='C_k = bar{C}_k'!$Z$44 -> 313.45784 | I19: ='C_k = bar{C}_k'!X45 -> 24 | J19: ='C_k = bar{C}_k'!Y45 -> 0.078431373 | K19: ='C_k = bar{C}_k'!$Z$45 -> 226.11024 | M19: ='C_k = bar{C}_k'!X46 -> 23 | N19: ='C_k = bar{C}_k'!Y46 -> 0.1554717 | O19: ='C_k = bar{C}_k'!$Z$46 -> 344.28692 | T19: 0.6 | U19: BM | V19: ='Otto benchmark'!X18 -> 25 | W19: ='Otto benchmark'!Y18 -> 25 | X19: ='Otto benchmark'!Z18 -> 0 | Y19: ='Otto benchmark'!AA18 -> 0 | Z19: ='Otto benchmark'!AB18 -> 0.41744 | AA19: ='Otto benchmark'!AC18 -> 1.58 | AE19: ='Classical benchmark'!G19 -> Mansoor | AF19: ='Classical benchmark'!H19 -> 11 | AG19: ='Classical benchmark'!J19 -> 3 | AH19: ='Classical benchmark'!K19 -> 0.001 | AI19: 3 | AJ19: ='Classical benchmark'!L19 -> 0 | AK19: 3 | AL19: ='Classical benchmark'!M19 -> 0.08 | AM19: ='Classical benchmark'!N19 -> 3
C20: 0.6 | D20: BM | E20: ='C_k = bar{C}_k'!X47 -> 25 | F20: ='C_k = bar{C}_k'!Y47 -> 0 | G20: ='C_k = bar{C}_k'!$Z$47 -> 0.74168 | I20: ='C_k = bar{C}_k'!X48 -> 25 | J20: ='C_k = bar{C}_k'!Y48 -> 0 | K20: ='C_k = bar{C}_k'!$Z$48 -> 0.91264 | M20: ='C_k = bar{C}_k'!X49 -> 25 | N20: ='C_k = bar{C}_k'!Y49 -> 0 | O20: ='C_k = bar{C}_k'!$Z$49 -> 1.06208 | U20: PB | V20: ='Otto benchmark'!X19 -> 25 | W20: ='Otto benchmark'!Y19 -> 25 | X20: ='Otto benchmark'!Z19 -> 0 | Y20: ='Otto benchmark'!AA19 -> 0 | Z20: ='Otto benchmark'!AB19 -> 0.09936 | AA20: ='Otto benchmark'!AC19 -> 0.56 | AE20: ='Classical benchmark'!G20 -> Mertens | AF20: ='Classical benchmark'!H20 -> 7 | AG20: ='Classical benchmark'!J20 -> 6 | AH20: ='Classical benchmark'!K20 -> 0.00066666667 | AI20: 6 | AJ20: ='Classical benchmark'!L20 -> 0 | AK20: 6 | AL20: ='Classical benchmark'!M20 -> 0.03 | AM20: ='Classical benchmark'!N20 -> 6
D21: PB | E21: ='C_k = bar{C}_k'!X50 -> 25 | F21: ='C_k = bar{C}_k'!Y50 -> 0 | G21: ='C_k = bar{C}_k'!$Z$50 -> 0.51896 | I21: ='C_k = bar{C}_k'!X51 -> 25 | J21: ='C_k = bar{C}_k'!Y51 -> 0 | K21: ='C_k = bar{C}_k'!$Z$51 -> 0.95644 | M21: ='C_k = bar{C}_k'!X52 -> 25 | N21: ='C_k = bar{C}_k'!Y52 -> 0 | O21: ='C_k = bar{C}_k'!$Z$52 -> 1.30596 | U21: PM | V21: ='Otto benchmark'!X20 -> 24 | W21: ='Otto benchmark'!Y20 -> 25 | X21: ='Otto benchmark'!Z20 -> 0.06779661 | Y21: ='Otto benchmark'!AA20 -> 0 | Z21: ='Otto benchmark'!AB20 -> 147.45496 | AA21: ='Otto benchmark'!AC20 -> 48.32 | AE21: ='Classical benchmark'!G21 -> Mitchell | AF21: ='Classical benchmark'!H21 -> 21 | AG21: ='Classical benchmark'!J21 -> 6 | AH21: ='Classical benchmark'!K21 -> 0.00083333333 | AI21: 6 | AJ21: ='Classical benchmark'!L21 -> 0 | AK21: 6 | AL21: ='Classical benchmark'!M21 -> 0.13 | AM21: ='Classical benchmark'!N21 -> 6
D22: PM | E22: ='C_k = bar{C}_k'!X53 -> 23 | F22: ='C_k = bar{C}_k'!Y53 -> 0.14622798 | G22: ='C_k = bar{C}_k'!$Z$53 -> 293.15116 | I22: ='C_k = bar{C}_k'!X54 -> 24 | J22: ='C_k = bar{C}_k'!Y54 -> 0.06779661 | K22: ='C_k = bar{C}_k'!$Z$54 -> 148.91804 | M22: ='C_k = bar{C}_k'!X55 -> 23 | N22: ='C_k = bar{C}_k'!Y55 -> 0.15390307 | O22: ='C_k = bar{C}_k'!$Z$55 -> 292.84492 | T22: 0.9 | U22: BM | V22: ='Otto benchmark'!X21 -> 25 | W22: ='Otto benchmark'!Y21 -> 25 | X22: ='Otto benchmark'!Z21 -> 0 | Y22: ='Otto benchmark'!AA21 -> 0 | Z22: ='Otto benchmark'!AB21 -> 0.10036 | AA22: ='Otto benchmark'!AC21 -> 0.08 | AE22: ='Classical benchmark'!G22 -> Mukherje | AF22: ='Classical benchmark'!H22 -> 94 | AG22: ='Classical benchmark'!J22 -> 13 | AH22: ='Classical benchmark'!K22 -> 20.371769 | AI22: 13 | AJ22: ='Classical benchmark'!L22 -> 5.61 | AK22: 13 | AL22: ='Classical benchmark'!M22 -> 76.92 | AM22: ='Classical benchmark'!N22 -> 13
C23: 0.9 | D23: BM | E23: ='C_k = bar{C}_k'!X56 -> 25 | F23: ='C_k = bar{C}_k'!Y56 -> 0 | G23: ='C_k = bar{C}_k'!$Z$56 -> 0.24252 | I23: ='C_k = bar{C}_k'!X57 -> 25 | J23: ='C_k = bar{C}_k'!Y57 -> 0 | K23: ='C_k = bar{C}_k'!$Z$57 -> 0.24292 | M23: ='C_k = bar{C}_k'!X58 -> 25 | N23: ='C_k = bar{C}_k'!Y58 -> 0 | O23: ='C_k = bar{C}_k'!$Z$58 -> 0.27144 | U23: PB | V23: ='Otto benchmark'!X22 -> 25 | W23: ='Otto benchmark'!Y22 -> 25 | X23: ='Otto benchmark'!Z22 -> 0 | Y23: ='Otto benchmark'!AA22 -> 0 | Z23: ='Otto benchmark'!AB22 -> 0.06196 | AA23: ='Otto benchmark'!AC22 -> 0.04 | AE23: ='Classical benchmark'!G23 -> Roszieg | AF23: ='Classical benchmark'!H23 -> 25 | AG23: ='Classical benchmark'!J23 -> 6 | AH23: ='Classical benchmark'!K23 -> 0.0011666667 | AI23: 6 | AJ23: ='Classical benchmark'!L23 -> 0 | AK23: 6 | AL23: ='Classical benchmark'!M23 -> 66.86 | AM23: ='Classical benchmark'!N23 -> 6
D24: PB | E24: ='C_k = bar{C}_k'!X59 -> 25 | F24: ='C_k = bar{C}_k'!Y59 -> 0 | G24: ='C_k = bar{C}_k'!$Z$59 -> 0.12684 | I24: ='C_k = bar{C}_k'!X60 -> 25 | J24: ='C_k = bar{C}_k'!Y60 -> 0 | K24: ='C_k = bar{C}_k'!$Z$60 -> 0.1292 | M24: ='C_k = bar{C}_k'!X61 -> 25 | N24: ='C_k = bar{C}_k'!Y61 -> 0 | O24: ='C_k = bar{C}_k'!$Z$61 -> 0.13068 | U24: PM | V24: ='Otto benchmark'!X23 -> 25 | W24: ='Otto benchmark'!Y23 -> 25 | X24: ='Otto benchmark'!Z23 -> 0 | Y24: ='Otto benchmark'!AA23 -> 0 | Z24: ='Otto benchmark'!AB23 -> 0.4416 | AA24: ='Otto benchmark'!AC23 -> 0.32 | AE24: ='Classical benchmark'!G24 -> Sawyer | AF24: ='Classical benchmark'!H24 -> 30 | AG24: ='Classical benchmark'!J24 -> 9 | AH24: ='Classical benchmark'!K24 -> 0.0017777778 | AI24: 9 | AJ24: ='Classical benchmark'!L24 -> 0.07 | AK24: 9 | AL24: ='Classical benchmark'!M24 -> 134.48 | AM24: ='Classical benchmark'!N24 -> 9
D25: PM | E25: ='C_k = bar{C}_k'!X62 -> 25 | F25: ='C_k = bar{C}_k'!Y62 -> 0 | G25: ='C_k = bar{C}_k'!$Z$62 -> 0.89756 | I25: ='C_k = bar{C}_k'!X63 -> 25 | J25: ='C_k = bar{C}_k'!Y63 -> 0 | K25: ='C_k = bar{C}_k'!$Z$63 -> 0.94496 | M25: ='C_k = bar{C}_k'!X64 -> 25 | N25: ='C_k = bar{C}_k'!Y64 -> 0 | O25: ='C_k = bar{C}_k'!$Z$64 -> 0.85068 | S25: Overall | V25: ='Otto benchmark'!X24 -> 517 | W25: ='Otto benchmark'!Y24 -> 502 | X25: ='Otto benchmark'!Z24 -> 0.033919324 | Y25: ='Otto benchmark'!AA24 -> 0.092380952 | Z25: ='Otto benchmark'!AB24 -> 57.421141 | AA25: ='Otto benchmark'!AC24 -> 375.90143 | AE25: ='Classical benchmark'!G25 -> Scholl | AF25: ='Classical benchmark'!H25 -> 297 | AG25: ='Classical benchmark'!J25 -> 26 | AH25: ='Classical benchmark'!K25 -> 2.8938077 | AI25: 26 | AJ25: ='Classical benchmark'!L25 -> 40.26 | AK25: 26 | AL25: ='Classical benchmark'!M25 -> 114.39 | AM25: ='Classical benchmark'!N25 -> 26
B26: Overall | E26: =SUM(E5:E25) -> 509 | F26: =AVERAGE(F5:F25) -> 0.063719407 | G26: =AVERAGE(G5:G25) -> 113.45686 | I26: =SUM(I5:I25) -> 510 | J26: =AVERAGE(J5:J25) -> 0.067845804 | K26: =AVERAGE(K5:K25) -> 113.10041 | M26: =SUM(M5:M25) -> 508 | N26: =AVERAGE(N5:N25) -> 0.094599149 | O26: =AVERAGE(O5:O25) -> 130.65069 | AE26: ='Classical benchmark'!G26 -> Tonge | AF26: ='Classical benchmark'!H26 -> 70 | AG26: ='Classical benchmark'!J26 -> 16 | AH26: ='Classical benchmark'!K26 -> 0.0834375 | AI26: 16 | AJ26: ='Classical benchmark'!L26 -> 0.1 | AK26: 16 | AL26: ='Classical benchmark'!M26 -> 15.74 | AM26: ='Classical benchmark'!N26 -> 16
AE27: ='Classical benchmark'!G27 -> Warnecke | AF27: ='Classical benchmark'!H27 -> 58 | AG27: ='Classical benchmark'!J27 -> 16 | AH27: ='Classical benchmark'!K27 -> 0.20075 | AI27: 16 | AJ27: ='Classical benchmark'!L27 -> 0.26 | AK27: 16 | AL27: ='Classical benchmark'!M27 -> 870.38 | AM27: ='Classical benchmark'!N27 -> 15
B28: Results for C_k = 2/3\bar{C}_k + 1/3 \underline{C} | AE28: ='Classical benchmark'!G28 -> Wee-Mag | AF28: ='Classical benchmark'!H28 -> 75 | AG28: ='Classical benchmark'!J28 -> 24 | AH28: ='Classical benchmark'!K28 -> 0.21675 | AI28: 24 | AJ28: ='Classical benchmark'!L28 -> 2.25 | AK28: 24 | AL28: ='Classical benchmark'!M28 -> 2.24 | AM28: ='Classical benchmark'!N28 -> 24
B29: Struct. | C29: OS | D29: TD | E29: Configuration K=2 | I29: Configuration K=3 | M29: Configuration K=4 | AE29: ='Classical benchmark'!G29 -> Overall | AG29: ='Classical benchmark'!J29 -> 269 | AH29: ='Classical benchmark'!K29 -> 1.6057249 | AI29: 269 | AJ29: ='Classical benchmark'!L29 -> 10.94 | AK29: 269 | AL29: ='Classical benchmark'!M29 -> 157.2 | AM29: ='Classical benchmark'!N29 -> 266
E30: opt | F30: gap(\%) | G30: total time | I30: opt | J30: gap(\%) | K30: total time | M30: opt | N30: gap(\%) | O30: total time
B31: BN | C31: 0.2 | D31: BM | E31: ='C_k = Ck(1)'!X2 -> 25 | F31: ='C_k = Ck(1)'!Y2 -> 0 | G31: ='C_k = Ck(1)'!Z2 -> 0.69228 | I31: ='C_k = Ck(1)'!X3 -> 25 | J31: ='C_k = Ck(1)'!Y3 -> 0 | K31: ='C_k = Ck(1)'!Z3 -> 0.70604 | M31: ='C_k = Ck(1)'!X4 -> 25 | N31: ='C_k = Ck(1)'!Y4 -> 0 | O31: ='C_k = Ck(1)'!Z4 -> 0.74496
D32: PB | E32: ='C_k = Ck(1)'!X5 -> 25 | F32: ='C_k = Ck(1)'!Y5 -> 0 | G32: ='C_k = Ck(1)'!Z5 -> 0.6222 | I32: ='C_k = Ck(1)'!X6 -> 25 | J32: ='C_k = Ck(1)'!Y6 -> 0 | K32: ='C_k = Ck(1)'!Z6 -> 0.681 | M32: ='C_k = Ck(1)'!X7 -> 23 | N32: ='C_k = Ck(1)'!Y7 -> 0.57142857 | O32: ='C_k = Ck(1)'!Z7 -> 303.94124
D33: PM | E33: ='C_k = Ck(1)'!X8 -> 23 | F33: ='C_k = Ck(1)'!Y8 -> 0.15686275 | G33: ='C_k = Ck(1)'!Z8 -> 302.00616 | I33: ='C_k = Ck(1)'!X9 -> 23 | J33: ='C_k = Ck(1)'!Y9 -> 0.15686275 | K33: ='C_k = Ck(1)'!Z9 -> 296.36952 | M33: ='C_k = Ck(1)'!X10 -> 22 | N33: ='C_k = Ck(1)'!Y10 -> 0.23093682 | O33: ='C_k = Ck(1)'!Z10 -> 462.78356
C34: 0.6 | D34: BM | E34: ='C_k = Ck(1)'!X11 -> 24 | F34: ='C_k = Ck(1)'!Y11 -> 0.18181818 | G34: ='C_k = Ck(1)'!Z11 -> 145.11436 | I34: ='C_k = Ck(1)'!X12 -> 23 | J34: ='C_k = Ck(1)'!Y12 -> 0.36363636 | K34: ='C_k = Ck(1)'!Z12 -> 289.2586 | M34: ='C_k = Ck(1)'!X13 -> 23 | N34: ='C_k = Ck(1)'!Y13 -> 0.52910053 | O34: ='C_k = Ck(1)'!Z13 -> 289.9374
D35: PB | E35: ='C_k = Ck(1)'!X14 -> 25 | F35: ='C_k = Ck(1)'!Y14 -> 0 | G35: ='C_k = Ck(1)'!Z14 -> 0.66312 | I35: ='C_k = Ck(1)'!X15 -> 25 | J35: ='C_k = Ck(1)'!Y15 -> 0 | K35: ='C_k = Ck(1)'!Z15 -> 1.09364 | M35: ='C_k = Ck(1)'!X16 -> 25 | N35: ='C_k = Ck(1)'!Y16 -> 0 | O35: ='C_k = Ck(1)'!Z16 -> 2.42504
D36: PM | E36: ='C_k = Ck(1)'!X17 -> 22 | F36: ='C_k = Ck(1)'!Y17 -> 0.23082615 | G36: ='C_k = Ck(1)'!Z17 -> 434.20252 | I36: ='C_k = Ck(1)'!X18 -> 23 | J36: ='C_k = Ck(1)'!Y18 -> 0.15250545 | K36: ='C_k = Ck(1)'!Z18 -> 297.6658 | M36: ='C_k = Ck(1)'!X19 -> 23 | N36: ='C_k = Ck(1)'!Y19 -> 0.15115865 | O36: ='C_k = Ck(1)'!Z19 -> 314.61948
B37: CH | C37: 0.2 | D37: BM | E37: ='C_k = Ck(1)'!X20 -> 25 | F37: ='C_k = Ck(1)'!Y20 -> 0 | G37: ='C_k = Ck(1)'!Z20 -> 0.84824 | I37: ='C_k = Ck(1)'!X21 -> 25 | J37: ='C_k = Ck(1)'!Y21 -> 0 | K37: ='C_k = Ck(1)'!Z21 -> 0.84768 | M37: ='C_k = Ck(1)'!X22 -> 25 | N37: ='C_k = Ck(1)'!Y22 -> 0 | O37: ='C_k = Ck(1)'!Z22 -> 0.8542
D38: PB | E38: ='C_k = Ck(1)'!X23 -> 25 | F38: ='C_k = Ck(1)'!Y23 -> 0 | G38: ='C_k = Ck(1)'!Z23 -> 0.44056 | I38: ='C_k = Ck(1)'!X24 -> 25 | J38: ='C_k = Ck(1)'!Y24 -> 0 | K38: ='C_k = Ck(1)'!Z24 -> 0.53868 | M38: ='C_k = Ck(1)'!X25 -> 24 | N38: ='C_k = Ck(1)'!Y25 -> 0.28571429 | O38: ='C_k = Ck(1)'!Z25 -> 145.07264
D39: PM | E39: ='C_k = Ck(1)'!X26 -> 22 | F39: ='C_k = Ck(1)'!Y26 -> 0.23686275 | G39: ='C_k = Ck(1)'!Z26 -> 447.68484 | I39: ='C_k = Ck(1)'!X27 -> 20 | J39: ='C_k = Ck(1)'!Y27 -> 0.38992397 | K39: ='C_k = Ck(1)'!Z27 -> 742.70248 | M39: ='C_k = Ck(1)'!X28 -> 20 | N39: ='C_k = Ck(1)'!Y28 -> 0.39391018 | O39: ='C_k = Ck(1)'!Z28 -> 806.91184
C40: 0.6 | D40: BM | E40: ='C_k = Ck(1)'!X29 -> 25 | F40: ='C_k = Ck(1)'!Y29 -> 0 | G40: ='C_k = Ck(1)'!Z29 -> 1.07384 | I40: ='C_k = Ck(1)'!X30 -> 24 | J40: ='C_k = Ck(1)'!Y30 -> 0.14814815 | K40: ='C_k = Ck(1)'!Z30 -> 145.3144 | M40: ='C_k = Ck(1)'!X31 -> 25 | N40: ='C_k = Ck(1)'!Y31 -> 0 | O40: ='C_k = Ck(1)'!Z31 -> 1.525
D41: PB | E41: ='C_k = Ck(1)'!X32 -> 25 | F41: ='C_k = Ck(1)'!Y32 -> 0 | G41: ='C_k = Ck(1)'!Z32 -> 0.388 | I41: ='C_k = Ck(1)'!X33 -> 25 | J41: ='C_k = Ck(1)'!Y33 -> 0 | K41: ='C_k = Ck(1)'!Z33 -> 1.05904 | M41: ='C_k = Ck(1)'!X34 -> 25 | N41: ='C_k = Ck(1)'!Y34 -> 0 | O41: ='C_k = Ck(1)'!Z34 -> 1.2046
...

Sheet Classical benchmark
A1: Problems and optimal solutions
A2: Precedence graph | B2: c | C2: m* | D2: time (total) | E2: time (LB)
A3: Arcus1 | B3: 3786 | C3: 41 | D3: 0.089 | E3: 0.031 | G3: Instances | H3: n | I3: |E| | J3: #I | K3: time BPC | L3: time BBR | M3: time B&B | N3: opt B&B
A4: Arcus1 | B4: 3985 | C4: 41 | D4: 0.061 | E4: 0.022 | G4: Arcus1 | H4: 83 | I4: 113 | J4: 16 | K4: =AVERAGE(D3:D18) -> 0.0289375 | L4: 0.22 | M4: 5.69 | N4: 16
A5: Arcus1 | B5: 4206 | C5: 41 | D5: 0.048 | E5: 0.021 | G5: Arcus2 | H5: 111 | I5: 176 | J5: 17 | K5: =AVERAGE(D19:D35) -> 0.43141176 | L5: 7.14 | M5: 211.49 | N5: 17
A6: Arcus1 | B6: 4454 | C6: 41 | D6: 0.03 | E6: 0.021 | G6: Barthold | H6: 148 | I6: 175 | J6: 8 | K6: =AVERAGE(D63:D70) -> 0.526125 | L6: 90.66 | M6: 4.41 | N6: 8
A7: Arcus1 | B7: 4732 | C7: 41 | D7: 0.021 | E7: 0.021 | G7: Barthold2 | H7: 148 | I7: 175 | J7: 27 | K7: =AVERAGE(D36:D62) -> 2.4512222 | L7: 29.66 | M7: 575.35 | N7: 25
A8: Arcus1 | B8: 5048 | C8: 41 | D8: 0.022 | E8: 0.021 | G8: Bowman | H8: 8 | I8: 8 | J8: 1 | K8: =AVERAGE(D71) -> 0.001 | L8: 0 | M8: 0.05 | N8: 1
A9: Arcus1 | B9: 5408 | C9: 41 | D9: 0.02 | E9: 0.02 | G9: Buxey | H9: 29 | I9: 36 | J9: 7 | K9: =AVERAGE(D72:D78) -> 0.0018571429 | L9: 0.03 | M9: 171.94 | N9: 7
A10: Arcus1 | B10: 5824 | C10: 41 | D10: 0.02 | E10: 0.02 | G10: Gunther | H10: 35 | I10: 45 | J10: 7 | K10: =AVERAGE(D79:D85) -> 0.0012857143 | L10: 0 | M10: 114.83 | N10: 7
A11: Arcus1 | B11: 5853 | C11: 41 | D11: 0.02 | E11: 0.02 | G11: Hahn | H11: 53 | I11: 82 | J11: 5 | K11: =AVERAGE(D86:D90) -> 0.006 | L11: 0.02 | M11: 0.22 | N11: 5
A12: Arcus1 | B12: 6309 | C12: 41 | D12: 0.02 | E12: 0.02 | G12: Heskiaoff | H12: 28 | I12: 39 | J12: 6 | K12: =AVERAGE(D91:D96) -> 0.0013333333 | L12: 0.05 | M12: 0.22 | N12: 6
A13: Arcus1 | B13: 6842 | C13: 41 | D13: 0.02 | E13: 0.02 | G13: Jackson | H13: 11 | I13: 13 | J13: 6 | K13: =AVERAGE(D97:D102) -> 0.001 | L13: 0 | M13: 0.06 | N13: 6
A14: Arcus1 | B14: 6883 | C14: 41 | D14: 0.019 | E14: 0.019 | G14: Jaeschke | H14: 9 | I14: 11 | J14: 5 | K14: =AVERAGE(D103:D107) -> 0.001 | L14: 0 | M14: 0.03 | N14: 5
A15: Arcus1 | B15: 7571 | C15: 41 | D15: 0.019 | E15: 0.019 | G15: Kilbridge | H15: 45 | I15: 62 | J15: 10 | K15: =AVERAGE(D108:D117) -> 0.0052 | L15: 0.04 | M15: 0.58 | N15: 10
A16: Arcus1 | B16: 8412 | C16: 41 | D16: 0.018 | E16: 0.018 | G16: Lutz1 | H16: 32 | I16: 38 | J16: 6 | K16: =AVERAGE(D118:D123) -> 0.0018333333 | L16: 0 | M16: 0.13 | N16: 6
A17: Arcus1 | B17: 8898 | C17: 41 | D17: 0.019 | E17: 0.019 | G17: Lutz2 | H17: 89 | I17: 118 | J17: 11 | K17: =AVERAGE(D124:D134) -> 0.32118182 | L17: 0.22 | M17: 106.99 | N17: 11
A18: Arcus1 | B18: 10816 | C18: 41 | D18: 0.017 | E18: 0.017 | G18: Lutz3 | H18: 89 | I18: 118 | J18: 12 | K18: =AVERAGE(D135:D146) -> 0.018916667 | L18: 0.03 | M18: 1.66 | N18: 12
A19: Arcus2 | B19: 5755 | C19: 31 | D19: 0.371 | E19: 0.025 | G19: Mansoor | H19: 11 | I19: 11 | J19: 3 | K19: =AVERAGE(D147:D149) -> 0.001 | L19: 0 | M19: 0.08 | N19: 3
A20: Arcus2 | B20: 5785 | C20: 31 | D20: 0.373 | E20: 0.024 | G20: Mertens | H20: 7 | I20: 6 | J20: 6 | K20: =AVERAGE(D150:D155) -> 0.00066666667 | L20: 0 | M20: 0.03 | N20: 6
A21: Arcus2 | B21: 6016 | C21: 30 | D21: 0.351 | E21: 0.024 | G21: Mitchell | H21: 21 | I21: 27 | J21: 6 | K21: =AVERAGE(D156:D161) -> 0.00083333333 | L21: 0 | M21: 0.13 | N21: 6
A22: Arcus2 | B22: 6267 | C22: 29 | D22: 1.584 | E22: 0.024 | G22: Mukherje | H22: 94 | I22: 181 | J22: 13 | K22: =AVERAGE(D162:D174) -> 20.371769 | L22: 5.61 | M22: 76.92 | N22: 13
A23: Arcus2 | B23: 6540 | C23: 29 | D23: 1.285 | E23: 0.03 | G23: Roszieg | H23: 25 | I23: 32 | J23: 6 | K23: =AVERAGE(D175:D180) -> 0.0011666667 | L23: 0 | M23: 66.86 | N23: 6
A24: Arcus2 | B24: 6837 | C24: 29 | D24: 1.121 | E24: 0.026 | G24: Sawyer | H24: 30 | I24: 32 | J24: 9 | K24: =AVERAGE(D181:D189) -> 0.0017777778 | L24: 0.07 | M24: 134.48 | N24: 9
A25: Arcus2 | B25: 7162 | C25: 27 | D25: 0.355 | E25: 0.025 | G25: Scholl | H25: 297 | I25: 423 | J25: 26 | K25: =AVERAGE(D190:D215) -> 2.8938077 | L25: 40.26 | M25: 114.39 | N25: 26
A26: Arcus2 | B26: 7520 | C26: 27 | D26: 0.278 | E26: 0.024 | G26: Tonge | H26: 70 | I26: 86 | J26: 16 | K26: =AVERAGE(D216:D231) -> 0.0834375 | L26: 0.1 | M26: 15.74 | N26: 16
A27: Arcus2 | B27: 7916 | C27: 27 | D27: 0.909 | E27: 0.025 | G27: Warnecke | H27: 58 | I27: 70 | J27: 16 | K27: =AVERAGE(D232:D247) -> 0.20075 | L27: 0.26 | M27: 870.38 | N27: 15
A28: Arcus2 | B28: 8356 | C28: 26 | D28: 0.218 | E28: 0.026 | G28: Wee-Mag | H28: 75 | I28: 24 | J28: 24 | K28: =AVERAGE(D248:D271) -> 0.21675 | L28: 2.25 | M28: 2.24 | N28: 24
A29: Arcus2 | B29: 8847 | C29: 26 | D29: 0.156 | E29: 0.027 | G29: Overall | J29: =SUM(J4:J28) -> 269 | K29: =AVERAGE(D3:D271) -> 1.6057249 | L29: 10.94 | M29: 157.2 | N29: =SUM(N4:N28) -> 266
A30: Arcus2 | B30: 9400 | C30: 26 | D30: 0.16 | E30: 0.025
A31: Arcus2 | B31: 10027 | C31: 26 | D31: 0.049 | E31: 0.025
A32: Arcus2 | B32: 10743 | C32: 26 | D32: 0.03 | E32: 0.024
A33: Arcus2 | B33: 11378 | C33: 26 | D33: 0.043 | E33: 0.04
A34: Arcus2 | B34: 11570 | C34: 26 | D34: 0.027 | E34: 0.025
A35: Arcus2 | B35: 17067 | C35: 26 | D35: 0.024 | E35: 0.024
A36: Barthol2 | B36: 84 | C36: 51 | D36: 1.196 | E36: 0.033
A37: Barthol2 | B37: 85 | C37: 50 | D37: 10.85 | E37: 0.032
A38: Barthol2 | B38: 87 | C38: 49 | D38: 1.343 | E38: 0.033
A39: Barthol2 | B39: 89 | C39: 48 | D39: 1.372 | E39: 0.035
A40: Barthol2 | B40: 91 | C40: 47 | D40: 1.313 | E40: 0.033
...

Sheet Otto benchmark
A1: 0 | B1: TD | C1: OS | D1: instances | E1: UB | F1: LB | G1: opt | H1: gap | I1: totalTime | J1: LBTime | K1: initTime | L1: pricingTime | M1: separateCPTime | N1: separateTCTime | O1: totalColNum | P1: CPcutNum | Q1: TCcutNum | R1: maxBBTreeDepth | S1: numNodeExplored
A2: 0 | B2: BM | C2: 0.2 | D2: 1 | E2: 23 | F2: 23 | G2: =IF(E2=F2,1,0) -> 1 | H2: =(E2-F2)/F2*100 -> 0 | I2: 0.599 | J2: 0.027 | K2: 0.572 | L2: 0 | M2: 0 | N2: 0 | O2: 0 | P2: 0 | Q2: 0 | R2: 0 | S2: 0 | U2: Struct. | V2: OS | W2: TD | X2: opt BPC | Y2: opt BBR | Z2: gap BPC | AA2: gap BBR | AB2: time BPC | AC2: time BBR
A3: 0 | B3: BM | C3: 0.2 | D3: 2 | E3: 21 | F3: 21 | G3: =IF(E3=F3,1,0) -> 1 | H3: =(E3-F3)/F3*100 -> 0 | I3: 0.574 | J3: 0.015 | K3: 0.559 | L3: 0 | M3: 0 | N3: 0 | O3: 0 | P3: 0 | Q3: 0 | R3: 0 | S3: 0 | U3: BN | V3: 0.2 | W3: BM | X3: =SUM(G2:G26) -> 25 | Y3: 25 | Z3: =AVERAGE(H2:H26) -> 0 | AA3: 0 | AB3: =AVERAGE(I2:I26) -> 0.59472 | AC3: 7.92
A4: 0 | B4: BM | C4: 0.2 | D4: 3 | E4: 20 | F4: 20 | G4: =IF(E4=F4,1,0) -> 1 | H4: =(E4-F4)/F4*100 -> 0 | I4: 0.438 | J4: 0.017 | K4: 0.421 | L4: 0 | M4: 0 | N4: 0 | O4: 0 | P4: 0 | Q4: 0 | R4: 0 | S4: 0 | W4: PB | X4: =SUM(G27:G51) -> 25 | Y4: 25 | Z4: =AVERAGE(H27:H51) -> 0 | AA4: 0 | AB4: =AVERAGE(I27:I51) -> 0.35476 | AC4: 7.54
A5: 0 | B5: BM | C5: 0.2 | D5: 4 | E5: 24 | F5: 24 | G5: =IF(E5=F5,1,0) -> 1 | H5: =(E5-F5)/F5*100 -> 0 | I5: 0.542 | J5: 0.018 | K5: 0.524 | L5: 0 | M5: 0 | N5: 0 | O5: 0 | P5: 0 | Q5: 0 | R5: 0 | S5: 0 | W5: PM | X5: =SUM(G52:G76) -> 23 | Y5: 16 | Z5: =AVERAGE(H52:H76) -> 0.15686275 | AA5: 0.74 | AB5: =AVERAGE(I52:I76) -> 293.12908 | AC5: 2768.85
A6: 0 | B6: BM | C6: 0.2 | D6: 5 | E6: 22 | F6: 22 | G6: =IF(E6=F6,1,0) -> 1 | H6: =(E6-F6)/F6*100 -> 0 | I6: 0.498 | J6: 0.017 | K6: 0.481 | L6: 0 | M6: 0 | N6: 0 | O6: 0 | P6: 0 | Q6: 0 | R6: 0 | S6: 0 | V6: 0.6 | W6: BM | X6: =SUM(G77:G101) -> 24 | Y6: 25 | Z6: =AVERAGE(H77:H101) -> 0.18181818 | AA6: 0 | AB6: =AVERAGE(I77:I101) -> 144.86004 | AC6: 29.72
A7: 0 | B7: BM | C7: 0.2 | D7: 6 | E7: 22 | F7: 22 | G7: =IF(E7=F7,1,0) -> 1 | H7: =(E7-F7)/F7*100 -> 0 | I7: 0.623 | J7: 0.017 | K7: 0.606 | L7: 0 | M7: 0 | N7: 0 | O7: 0 | P7: 0 | Q7: 0 | R7: 0 | S7: 0 | W7: PB | X7: =SUM(G102:G126) -> 25 | Y7: 25 | Z7: =AVERAGE(H102:H126) -> 0 | AA7: 0 | AB7: =AVERAGE(I102:I126) -> 0.13908 | AC7: 2.29
A8: 0 | B8: BM | C8: 0.2 | D8: 7 | E8: 26 | F8: 26 | G8: =IF(E8=F8,1,0) -> 1 | H8: =(E8-F8)/F8*100 -> 0 | I8: 0.494 | J8: 0.016 | K8: 0.478 | L8: 0 | M8: 0 | N8: 0 | O8: 0 | P8: 0 | Q8: 0 | R8: 0 | S8: 0 | W8: PM | X8: =SUM(G127:G151) -> 24 | Y8: 25 | Z8: =AVERAGE(H127:H151) -> 0.078431373 | AA8: 0 | AB8: =AVERAGE(I127:I151) -> 145.64512 | AC8: 68.38
A9: 0 | B9: BM | C9: 0.2 | D9: 8 | E9: 24 | F9: 24 | G9: =IF(E9=F9,1,0) -> 1 | H9: =(E9-F9)/F9*100 -> 0 | I9: 0.507 | J9: 0.017 | K9: 0.49 | L9: 0 | M9: 0 | N9: 0 | O9: 0 | P9: 0 | Q9: 0 | R9: 0 | S9: 0 | U9: CH | V9: 0.2 | W9: BM | X9: =SUM(G152:G176) -> 25 | Y9: 25 | Z9: =AVERAGE(H152:H176) -> 0 | AA9: 0 | AB9: =AVERAGE(I152:I176) -> 0.69992 | AC9: 5.09
A10: 0 | B10: BM | C10: 0.2 | D10: 9 | E10: 23 | F10: 23 | G10: =IF(E10=F10,1,0) -> 1 | H10: =(E10-F10)/F10*100 -> 0 | I10: 0.537 | J10: 0.018 | K10: 0.519 | L10: 0 | M10: 0 | N10: 0 | O10: 0 | P10: 0 | Q10: 0 | R10: 0 | S10: 0 | W10: PB | X10: =SUM(G177:G201) -> 25 | Y10: 25 | Z10: =AVERAGE(H177:H201) -> 0 | AA10: 0 | AB10: =AVERAGE(I177:I201) -> 0.27628 | AC10: 5.42
A11: 0 | B11: BM | C11: 0.2 | D11: 10 | E11: 22 | F11: 22 | G11: =IF(E11=F11,1,0) -> 1 | H11: =(E11-F11)/F11*100 -> 0 | I11: 0.443 | J11: 0.016 | K11: 0.427 | L11: 0 | M11: 0 | N11: 0 | O11: 0 | P11: 0 | Q11: 0 | R11: 0 | S11: 0 | W11: PM | X11: =SUM(G202:G226) -> 23 | Y11: 18 | Z11: =AVERAGE(H202:H226) -> 0.15843137 | AA11: 0.54 | AB11: =AVERAGE(I202:I226) -> 305.39436 | AC11: 2582.75
A12: 0 | B12: BM | C12: 0.2 | D12: 11 | E12: 24 | F12: 24 | G12: =IF(E12=F12,1,0) -> 1 | H12: =(E12-F12)/F12*100 -> 0 | I12: 0.666 | J12: 0.017 | K12: 0.649 | L12: 0 | M12: 0 | N12: 0 | O12: 0 | P12: 0 | Q12: 0 | R12: 0 | S12: 0 | V12: 0.6 | W12: BM | X12: =SUM(G227:G251) -> 25 | Y12: 25 | Z12: =AVERAGE(H227:H251) -> 0 | AA12: 0 | AB12: =AVERAGE(I227:I251) -> 0.6276 | AC12: 1.39
A13: 0 | B13: BM | C13: 0.2 | D13: 12 | E13: 25 | F13: 25 | G13: =IF(E13=F13,1,0) -> 1 | H13: =(E13-F13)/F13*100 -> 0 | I13: 0.73 | J13: 0.024 | K13: 0.706 | L13: 0 | M13: 0 | N13: 0 | O13: 0 | P13: 0 | Q13: 0 | R13: 0 | S13: 0 | W13: PB | X13: =SUM(G252:G276) -> 25 | Y13: 25 | Z13: =AVERAGE(H252:H276) -> 0 | AA13: 0 | AB13: =AVERAGE(I252:I276) -> 0.09524 | AC13: 0.52
A14: 0 | B14: BM | C14: 0.2 | D14: 13 | E14: 24 | F14: 24 | G14: =IF(E14=F14,1,0) -> 1 | H14: =(E14-F14)/F14*100 -> 0 | I14: 0.611 | J14: 0.024 | K14: 0.587 | L14: 0 | M14: 0 | N14: 0 | O14: 0 | P14: 0 | Q14: 0 | R14: 0 | S14: 0 | W14: PM | X14: =SUM(G277:G301) -> 24 | Y14: 25 | Z14: =AVERAGE(H277:H301) -> 0.068965517 | AA14: 0 | AB14: =AVERAGE(I277:I301) -> 145.825 | AC14: 34.83
A15: 0 | B15: BM | C15: 0.2 | D15: 14 | E15: 21 | F15: 21 | G15: =IF(E15=F15,1,0) -> 1 | H15: =(E15-F15)/F15*100 -> 0 | I15: 0.538 | J15: 0.025 | K15: 0.513 | L15: 0 | M15: 0 | N15: 0 | O15: 0 | P15: 0 | Q15: 0 | R15: 0 | S15: 0 | U15: MIXED | V15: 0.2 | W15: BM | X15: =SUM(G302:G326) -> 25 | Y15: 25 | Z15: =AVERAGE(H302:H326) -> 0 | AA15: 0 | AB15: =AVERAGE(I302:I326) -> 0.78948 | AC15: 9.08
A16: 0 | B16: BM | C16: 0.2 | D16: 15 | E16: 24 | F16: 24 | G16: =IF(E16=F16,1,0) -> 1 | H16: =(E16-F16)/F16*100 -> 0 | I16: 0.662 | J16: 0.026 | K16: 0.636 | L16: 0 | M16: 0 | N16: 0 | O16: 0 | P16: 0 | Q16: 0 | R16: 0 | S16: 0 | W16: PB | X16: =SUM(G327:G351) -> 25 | Y16: 25 | Z16: =AVERAGE(H327:H351) -> 0 | AA16: 0 | AB16: =AVERAGE(I327:I351) -> 0.443 | AC16: 6.64
A17: 0 | B17: BM | C17: 0.2 | D17: 16 | E17: 23 | F17: 23 | G17: =IF(E17=F17,1,0) -> 1 | H17: =(E17-F17)/F17*100 -> 0 | I17: 0.638 | J17: 0.028 | K17: 0.61 | L17: 0 | M17: 0 | N17: 0 | O17: 0 | P17: 0 | Q17: 0 | R17: 0 | S17: 0 | W17: PM | X17: =SUM(G352:G376) -> 25 | Y17: 18 | Z17: =AVERAGE(H352:H376) -> 0 | AA17: 0.66 | AB17: =AVERAGE(I352:I376) -> 18.3946 | AC17: 2312.61
A18: 0 | B18: BM | C18: 0.2 | D18: 17 | E18: 21 | F18: 21 | G18: =IF(E18=F18,1,0) -> 1 | H18: =(E18-F18)/F18*100 -> 0 | I18: 0.666 | J18: 0.023 | K18: 0.643 | L18: 0 | M18: 0 | N18: 0 | O18: 0 | P18: 0 | Q18: 0 | R18: 0 | S18: 0 | V18: 0.6 | W18: BM | X18: =SUM(G377:G401) -> 25 | Y18: 25 | Z18: =AVERAGE(H377:H401) -> 0 | AA18: 0 | AB18: =AVERAGE(I377:I401) -> 0.41744 | AC18: 1.58
A19: 0 | B19: BM | C19: 0.2 | D19: 18 | E19: 20 | F19: 20 | G19: =IF(E19=F19,1,0) -> 1 | H19: =(E19-F19)/F19*100 -> 0 | I19: 0.534 | J19: 0.018 | K19: 0.516 | L19: 0 | M19: 0 | N19: 0 | O19: 0 | P19: 0 | Q19: 0 | R19: 0 | S19: 0 | W19: PB | X19: =SUM(G402:G426) -> 25 | Y19: 25 | Z19: =AVERAGE(H402:H426) -> 0 | AA19: 0 | AB19: =AVERAGE(I402:I426) -> 0.09936 | AC19: 0.56
A20: 0 | B20: BM | C20: 0.2 | D20: 19 | E20: 23 | F20: 23 | G20: =IF(E20=F20,1,0) -> 1 | H20: =(E20-F20)/F20*100 -> 0 | I20: 0.573 | J20: 0.018 | K20: 0.555 | L20: 0 | M20: 0 | N20: 0 | O20: 0 | P20: 0 | Q20: 0 | R20: 0 | S20: 0 | W20: PM | X20: =SUM(G427:G451) -> 24 | Y20: 25 | Z20: =AVERAGE(H427:H451) -> 0.06779661 | AA20: 0 | AB20: =AVERAGE(I427:I451) -> 147.45496 | AC20: 48.32
A21: 0 | B21: BM | C21: 0.2 | D21: 20 | E21: 21 | F21: 21 | G21: =IF(E21=F21,1,0) -> 1 | H21: =(E21-F21)/F21*100 -> 0 | I21: 0.472 | J21: 0.016 | K21: 0.456 | L21: 0 | M21: 0 | N21: 0 | O21: 0 | P21: 0 | Q21: 0 | R21: 0 | S21: 0 | V21: 0.9 | W21: BM | X21: =SUM(G452:G476) -> 25 | Y21: 25 | Z21: =AVERAGE(H452:H476) -> 0 | AA21: 0 | AB21: =AVERAGE(I452:I476) -> 0.10036 | AC21: 0.08
A22: 0 | B22: BM | C22: 0.2 | D22: 21 | E22: 21 | F22: 21 | G22: =IF(E22=F22,1,0) -> 1 | H22: =(E22-F22)/F22*100 -> 0 | I22: 0.776 | J22: 0.025 | K22: 0.751 | L22: 0 | M22: 0 | N22: 0 | O22: 0 | P22: 0 | Q22: 0 | R22: 0 | S22: 0 | W22: PB | X22: =SUM(G477:G501) -> 25 | Y22: 25 | Z22: =AVERAGE(H477:H501) -> 0 | AA22: 0 | AB22: =AVERAGE(I477:I501) -> 0.06196 | AC22: 0.04
A23: 0 | B23: BM | C23: 0.2 | D23: 22 | E23: 24 | F23: 24 | G23: =IF(E23=F23,1,0) -> 1 | H23: =(E23-F23)/F23*100 -> 0 | I23: 0.721 | J23: 0.023 | K23: 0.698 | L23: 0 | M23: 0 | N23: 0 | O23: 0 | P23: 0 | Q23: 0 | R23: 0 | S23: 0 | W23: PM | X23: =SUM(G502:G526) -> 25 | Y23: 25 | Z23: =AVERAGE(H502:H526) -> 0 | AA23: 0 | AB23: =AVERAGE(I502:I526) -> 0.4416 | AC23: 0.32
A24: 0 | B24: BM | C24: 0.2 | D24: 23 | E24: 24 | F24: 24 | G24: =IF(E24=F24,1,0) -> 1 | H24: =(E24-F24)/F24*100 -> 0 | I24: 0.638 | J24: 0.028 | K24: 0.61 | L24: 0 | M24: 0 | N24: 0 | O24: 0 | P24: 0 | Q24: 0 | R24: 0 | S24: 0 | U24: Overall | X24: =SUM(X3:X23) -> 517 | Y24: =SUM(Y3:Y23) -> 502 | Z24: =AVERAGE(Z3:Z23) -> 0.033919324 | AA24: =AVERAGE(AA3:AA23) -> 0.092380952 | AB24: =AVERAGE(AB3:AB23) -> 57.421141 | AC24: =AVERAGE(AC3:AC23) -> 375.90143
A25: 1 | B25: BM | C25: 0.2 | D25: 24 | E25: 24 | F25: 24 | G25: =IF(E25=F25,1,0) -> 1 | H25: =(E25-F25)/F25*100 -> 0 | I25: 0.702 | J25: 0.024 | K25: 0.678 | L25: 0 | M25: 0 | N25: 0 | O25: 0 | P25: 0 | Q25: 0 | R25: 0 | S25: 0
A26: 0 | B26: BM | C26: 0.2 | D26: 25 | E26: 22 | F26: 22 | G26: =IF(E26=F26,1,0) -> 1 | H26: =(E26-F26)/F26*100 -> 0 | I26: 0.686 | J26: 0.023 | K26: 0.663 | L26: 0 | M26: 0 | N26: 0 | O26: 0 | P26: 0 | Q26: 0 | R26: 0 | S26: 0
A27: 0 | B27: PB | C27: 0.2 | D27: 26 | E27: 14 | F27: 14 | G27: =IF(E27=F27,1,0) -> 1 | H27: =(E27-F27)/F27*100 -> 0 | I27: 0.432 | J27: 0.022 | K27: 0.41 | L27: 0 | M27: 0 | N27: 0 | O27: 0 | P27: 0 | Q27: 0 | R27: 0 | S27: 0
A28: 0 | B28: PB | C28: 0.2 | D28: 27 | E28: 14 | F28: 14 | G28: =IF(E28=F28,1,0) -> 1 | H28: =(E28-F28)/F28*100 -> 0 | I28: 0.325 | J28: 0.021 | K28: 0.304 | L28: 0 | M28: 0 | N28: 0 | O28: 0 | P28: 0 | Q28: 0 | R28: 0 | S28: 0
A29: 0 | B29: PB | C29: 0.2 | D29: 28 | E29: 15 | F29: 15 | G29: =IF(E29=F29,1,0) -> 1 | H29: =(E29-F29)/F29*100 -> 0 | I29: 0.347 | J29: 0.02 | K29: 0.327 | L29: 0 | M29: 0 | N29: 0 | O29: 0 | P29: 0 | Q29: 0 | R29: 0 | S29: 0
A30: 0 | B30: PB | C30: 0.2 | D30: 29 | E30: 14 | F30: 14 | G30: =IF(E30=F30,1,0) -> 1 | H30: =(E30-F30)/F30*100 -> 0 | I30: 0.498 | J30: 0.019 | K30: 0.479 | L30: 0 | M30: 0 | N30: 0 | O30: 0 | P30: 0 | Q30: 0 | R30: 0 | S30: 0
A31: 0 | B31: PB | C31: 0.2 | D31: 30 | E31: 15 | F31: 15 | G31: =IF(E31=F31,1,0) -> 1 | H31: =(E31-F31)/F31*100 -> 0 | I31: 0.3 | J31: 0.014 | K31: 0.286 | L31: 0 | M31: 0 | N31: 0 | O31: 0 | P31: 0 | Q31: 0 | R31: 0 | S31: 0
A32: 0 | B32: PB | C32: 0.2 | D32: 31 | E32: 14 | F32: 14 | G32: =IF(E32=F32,1,0) -> 1 | H32: =(E32-F32)/F32*100 -> 0 | I32: 0.232 | J32: 0.015 | K32: 0.217 | L32: 0 | M32: 0 | N32: 0 | O32: 0 | P32: 0 | Q32: 0 | R32: 0 | S32: 0
A33: 0 | B33: PB | C33: 0.2 | D33: 32 | E33: 14 | F33: 14 | G33: =IF(E33=F33,1,0) -> 1 | H33: =(E33-F33)/F33*100 -> 0 | I33: 0.28 | J33: 0.014 | K33: 0.266 | L33: 0 | M33: 0 | N33: 0 | O33: 0 | P33: 0 | Q33: 0 | R33: 0 | S33: 0
A34: 0 | B34: PB | C34: 0.2 | D34: 33 | E34: 15 | F34: 15 | G34: =IF(E34=F34,1,0) -> 1 | H34: =(E34-F34)/F34*100 -> 0 | I34: 0.311 | J34: 0.013 | K34: 0.298 | L34: 0 | M34: 0 | N34: 0 | O34: 0 | P34: 0 | Q34: 0 | R34: 0 | S34: 0
A35: 0 | B35: PB | C35: 0.2 | D35: 34 | E35: 15 | F35: 15 | G35: =IF(E35=F35,1,0) -> 1 | H35: =(E35-F35)/F35*100 -> 0 | I35: 0.305 | J35: 0.014 | K35: 0.291 | L35: 0 | M35: 0 | N35: 0 | O35: 0 | P35: 0 | Q35: 0 | R35: 0 | S35: 0
A36: 0 | B36: PB | C36: 0.2 | D36: 35 | E36: 16 | F36: 16 | G36: =IF(E36=F36,1,0) -> 1 | H36: =(E36-F36)/F36*100 -> 0 | I36: 0.327 | J36: 0.014 | K36: 0.313 | L36: 0 | M36: 0 | N36: 0 | O36: 0 | P36: 0 | Q36: 0 | R36: 0 | S36: 0
... A525: 1 | B525: PM | C525: 0.9 | D525: 524 | E525: 65 | F525: 65 | G525: =IF(E525=F525,1,0) -> 1 | H525: =(E525-F525)/F525*100 -> 0 | I525: 0.05 | J525: 0.043 | K525: 0.007 | L525: 0 | M525: 0 | N525: 0 | O525: 0 | P525: 0 | Q525: 0 | R525: 0 | S525: 0
B526: PM | C526: 0.9 | D526: 525 | E526: 66 | F526: 66 | G526: =IF(E526=F526,1,0) -> 1 | H526: =(E526-F526)/F526*100 -> 0 | I526: 1.007 | J526: 0.043 | K526: 0.964 | L526: 0 | M526: 0 | N526: 0 | O526: 0 | P526: 0 | Q526: 0 | R526: 0 | S526: 0

Sheet C_k = bar{C}_k
B1: TD | C1: OS | D1: configuration | E1: instances | F1: UB | G1: LB | H1: opt | I1: gap | J1: totalTime | K1: LBTime | L1: initTime | M1: pricingTime | N1: separateCPTime | O1: separateTCTime | P1: totalColNum | Q1: CPcutNum | R1: TCcutNum | S1: maxBBTreeDepth | T1: numNodeExplored | U1: feasibility | W1: config | X1: opt | Y1: gap | Z1: total time | AA1: initial time | AB1: pricing time | AC1: separation_time | AD1: column_num | AE1: cut_num | AF1: num_node
A2: 0 | B2: BM | C2: 0.2 | D2: 2 | E2: 1 | F2: 23 | G2: 23 | H2: =IF(F2=G2,1,0) -> 1 | I2: =(F2-G2)/G2*100 -> 0 | J2: 0.569 | K2: 0.031 | L2: 0.538 | M2: 0 | N2: 0 | O2: 0 | P2: 0 | Q2: 0 | R2: 0 | S2: 0 | T2: 0 | U2: 1 | W2: 2 | X2: =SUMPRODUCT((MOD(ROW(H2:H76),3)=2)*H2:H76) -> 25 | Y2: =SUMPRODUCT((MOD(ROW(I2:I76),3)=2)*I2:I76)/25 -> 0 | Z2: =SUMPRODUCT((MOD(ROW(J2:J76),3)=2)*J2:J76)/25 -> 0.65036 | AA2: =SUMPRODUCT((MOD(ROW(L2:L76),3)=2)*L2:L76)/25 -> 0.62624 | AB2: =SUMPRODUCT((MOD(ROW(M2:M76),3)=2)*M2:M76)/25 -> 0 | AC2: =SUMPRODUCT((MOD(ROW(N2:N76),3)=2)*N2:N76)/25 -> 0 | AD2: =SUMPRODUCT((MOD(ROW(P2:P76),3)=2)*P2:P76)/25 -> 0 | AE2: =SUMPRODUCT((MOD(ROW(Q2:Q76),3)=2)*Q2:Q76)/25 -> 0 | AF2: =SUMPRODUCT((MOD(ROW(T2:T76),3)=2)*T2:T76)/25 -> 0
A3: 0 | B3: BM | C3: 0.2 | D3: 3 | E3: 1 | F3: 23 | G3: 23 | H3: =IF(F3=G3,1,0) -> 1 | I3: =(F3-G3)/G3*100 -> 0 | J3: 0.568 | K3: 0.017 | L3: 0.551 | M3: 0 | N3: 0 | O3: 0 | P3: 0 | Q3: 0 | R3: 0 | S3: 0 | T3: 0 | U3: 1 | W3: 3 | X3: =SUMPRODUCT((MOD(ROW(H2:H76),3)=0)*H2:H76) -> 25 | Y3: =SUMPRODUCT((MOD(ROW(I2:I76),3)=0)*I2:I76)/25 -> 0 | Z3: =SUMPRODUCT((MOD(ROW(J2:J76),3)=0)*J2:J76)/25 -> 0.66044 | AA3: =SUMPRODUCT((MOD(ROW(L2:L76),3)=0)*L2:L76)/25 -> 0.637 | AB3: =SUMPRODUCT((MOD(ROW(M2:M76),3)=0)*M2:M76)/25 -> 0 | AC3: =SUMPRODUCT((MOD(ROW(N2:N76),3)=0)*N2:N76)/25 -> 0 | AD3: =SUMPRODUCT((MOD(ROW(P2:P76),3)=0)*P2:P76)/25 -> 0 | AE3: =SUMPRODUCT((MOD(ROW(Q2:Q76),3)=0)*Q2:Q76)/25 -> 0 | AF3: =SUMPRODUCT((MOD(ROW(T2:T76),3)=0)*T2:T76)/25 -> 0
A4: 0 | B4: BM | C4: 0.2 | D4: 4 | E4: 1 | F4: 23 | G4: 23 | H4: =IF(F4=G4,1,0) -> 1 | I4: =(F4-G4)/G4*100 -> 0 | J4: 0.534 | K4: 0.016 | L4: 0.518 | M4: 0 | N4: 0 | O4: 0 | P4: 0 | Q4: 0 | R4: 0 | S4: 0 | T4: 0 | U4: 1 | W4: 4 | X4: =SUMPRODUCT((MOD(ROW(H2:H76),3)=1)*H2:H76) -> 25 | Y4: =SUMPRODUCT((MOD(ROW(I2:I76),3)=1)*I2:I76)/25 -> 0 | Z4: =SUMPRODUCT((MOD(ROW(J2:J76),3)=1)*J2:J76)/25 -> 0.7016 | AA4: =SUMPRODUCT((MOD(ROW(L2:L76),3)=1)*L2:L76)/25 -> 0.67796 | AB4: =SUMPRODUCT((MOD(ROW(M2:M76),3)=1)*M2:M76)/25 -> 0 | AC4: =SUMPRODUCT((MOD(ROW(N2:N76),3)=1)*N2:N76)/25 -> 0 | AD4: =SUMPRODUCT((MOD(ROW(P2:P76),3)=1)*P2:P76)/25 -> 0 | AE4: =SUMPRODUCT((MOD(ROW(Q2:Q76),3)=1)*Q2:Q76)/25 -> 0 | AF4: =SUMPRODUCT((MOD(ROW(T2:T76),3)=1)*T2:T76)/25 -> 0
A5: 0 | B5: BM | C5: 0.2 | D5: 2 | E5: 2 | F5: 21 | G5: 21 | H5: =IF(F5=G5,1,0) -> 1 | I5: =(F5-G5)/G5*100 -> 0 | J5: 0.583 | K5: 0.017 | L5: 0.566 | M5: 0 | N5: 0 | O5: 0 | P5: 0 | Q5: 0 | R5: 0 | S5: 0 | T5: 0 | U5: 1 | W5: 2 | X5: =SUMPRODUCT((MOD(ROW(H77:H151),3)=2)*H77:H151) -> 25 | Y5: =SUMPRODUCT((MOD(ROW(I77:I151),3)=2)*I77:I151)/25 -> 0 | Z5: =SUMPRODUCT((MOD(ROW(J77:J151),3)=2)*J77:J151)/25 -> 0.59804 | AA5: =SUMPRODUCT((MOD(ROW(L77:L151),3)=2)*L77:L151)/25 -> 0.573 | AB5: =SUMPRODUCT((MOD(ROW(M77:M151),3)=2)*M77:M151)/25 -> 0 | AC5: =SUMPRODUCT((MOD(ROW(N77:N151),3)=2)*N77:N151)/25 -> 0 | AD5: =SUMPRODUCT((MOD(ROW(P77:P151),3)=2)*P77:P151)/25 -> 0 | AE5: =SUMPRODUCT((MOD(ROW(Q77:Q151),3)=2)*Q77:Q151)/25 -> 0 | AF5: =SUMPRODUCT((MOD(ROW(T77:T151),3)=2)*T77:T151)/25 -> 0
A6: 0 | B6: BM | C6: 0.2 | D6: 3 | E6: 2 | F6: 21 | G6: 21 | H6: =IF(F6=G6,1,0) -> 1 | I6: =(F6-G6)/G6*100 -> 0 | J6: 0.584 | K6: 0.016 | L6: 0.568 | M6: 0 | N6: 0 | O6: 0 | P6: 0 | Q6: 0 | R6: 0 | S6: 0 | T6: 0 | U6: 1 | W6: 3 | X6: =SUMPRODUCT((MOD(ROW(H77:H151),3)=0)*H77:H151) -> 25 | Y6: =SUMPRODUCT((MOD(ROW(I77:I151),3)=0)*I77:I151)/25 -> 0 | Z6: =SUMPRODUCT((MOD(ROW(J77:J151),3)=0)*J77:J151)/25 -> 0.66828 | AA6: =SUMPRODUCT((MOD(ROW(L77:L151),3)=0)*L77:L151)/25 -> 0.64368 | AB6: =SUMPRODUCT((MOD(ROW(M77:M151),3)=0)*M77:M151)/25 -> 0 | AC6: =SUMPRODUCT((MOD(ROW(N77:N151),3)=0)*N77:N151)/25 -> 0 | AD6: =SUMPRODUCT((MOD(ROW(P77:P151),3)=0)*P77:P151)/25 -> 0 | AE6: =SUMPRODUCT((MOD(ROW(Q77:Q151),3)=0)*Q77:Q151)/25 -> 0 | AF6: =SUMPRODUCT((MOD(ROW(T77:T151),3)=0)*T77:T151)/25 -> 0
A7: 0 | B7: BM | C7: 0.2 | D7: 4 | E7: 2 | F7: 21 | G7: 21 | H7: =IF(F7=G7,1,0) -> 1 | I7: =(F7-G7)/G7*100 -> 0 | J7: 0.639 | K7: 0.016 | L7: 0.623 | M7: 0 | N7: 0 | O7: 0 | P7: 0 | Q7: 0 | R7: 0 | S7: 0 | T7: 0 | U7: 1 | W7: 4 | X7: =SUMPRODUCT((MOD(ROW(H77:H151),3)=1)*H77:H151) -> 24 | Y7: =SUMPRODUCT((MOD(ROW(I77:I151),3)=1)*I77:I151)/25 -> 0.28571429 | Z7: =SUMPRODUCT((MOD(ROW(J77:J151),3)=1)*J77:J151)/25 -> 181.76604 | AA7: =SUMPRODUCT((MOD(ROW(L77:L151),3)=1)*L77:L151)/25 -> 2.60532 | AB7: =SUMPRODUCT((MOD(ROW(M77:M151),3)=1)*M77:M151)/25 -> 13.3568 | AC7: =SUMPRODUCT((MOD(ROW(N77:N151),3)=1)*N77:N151)/25 -> 0.05964 | AD7: =SUMPRODUCT((MOD(ROW(P77:P151),3)=1)*P77:P151)/25 -> 5396.92 | AE7: =SUMPRODUCT((MOD(ROW(Q77:Q151),3)=1)*Q77:Q151)/25 -> 810.32 | AF7: =SUMPRODUCT((MOD(ROW(T77:T151),3)=1)*T77:T151)/25 -> 122.28
A8: 0 | B8: BM | C8: 0.2 | D8: 2 | E8: 3 | F8: 20 | G8: 20 | H8: =IF(F8=G8,1,0) -> 1 | I8: =(F8-G8)/G8*100 -> 0 | J8: 0.544 | K8: 0.018 | L8: 0.526 | M8: 0 | N8: 0 | O8: 0 | P8: 0 | Q8: 0 | R8: 0 | S8: 0 | T8: 0 | U8: 1 | W8: 2 | X8: =SUMPRODUCT((MOD(ROW(H152:H226),3)=2)*H152:H226) -> 22 | Y8: =SUMPRODUCT((MOD(ROW(I152:I226),3)=2)*I152:I226)/25 -> 0.23378582 | Z8: =SUMPRODUCT((MOD(ROW(J152:J226),3)=2)*J152:J226)/25 -> 454.1422 | AA8: =SUMPRODUCT((MOD(ROW(L152:L226),3)=2)*L152:L226)/25 -> 2.6262 | AB8: =SUMPRODUCT((MOD(ROW(M152:M226),3)=2)*M152:M226)/25 -> 0.70648 | AC8: =SUMPRODUCT((MOD(ROW(N152:N226),3)=2)*N152:N226)/25 -> 0.28396 | AD8: =SUMPRODUCT((MOD(ROW(P152:P226),3)=2)*P152:P226)/25 -> 2415.76 | AE8: =SUMPRODUCT((MOD(ROW(Q152:Q226),3)=2)*Q152:Q226)/25 -> 153.32 | AF8: =SUMPRODUCT((MOD(ROW(T152:T226),3)=2)*T152:T226)/25 -> 128.28
A9: 0 | B9: BM | C9: 0.2 | D9: 3 | E9: 3 | F9: 20 | G9: 20 | H9: =IF(F9=G9,1,0) -> 1 | I9: =(F9-G9)/G9*100 -> 0 | J9: 0.551 | K9: 0.025 | L9: 0.526 | M9: 0 | N9: 0 | O9: 0 | P9: 0 | Q9: 0 | R9: 0 | S9: 0 | T9: 0 | U9: 1 | W9: 3 | X9: =SUMPRODUCT((MOD(ROW(H152:H226),3)=0)*H152:H226) -> 23 | Y9: =SUMPRODUCT((MOD(ROW(I152:I226),3)=0)*I152:I226)/25 -> 0.15535445 | Z9: =SUMPRODUCT((MOD(ROW(J152:J226),3)=0)*J152:J226)/25 -> 365.99952 | AA9: =SUMPRODUCT((MOD(ROW(L152:L226),3)=0)*L152:L226)/25 -> 2.2632 | AB9: =SUMPRODUCT((MOD(ROW(M152:M226),3)=0)*M152:M226)/25 -> 0.66832 | AC9: =SUMPRODUCT((MOD(ROW(N152:N226),3)=0)*N152:N226)/25 -> 0.34164 | AD9: =SUMPRODUCT((MOD(ROW(P152:P226),3)=0)*P152:P226)/25 -> 1967.32 | AE9: =SUMPRODUCT((MOD(ROW(Q152:Q226),3)=0)*Q152:Q226)/25 -> 444.36 | AF9: =SUMPRODUCT((MOD(ROW(T152:T226),3)=0)*T152:T226)/25 -> 239.04
A10: 0 | B10: BM | C10: 0.2 | D10: 4 | E10: 3 | F10: 20 | G10: 20 | H10: =IF(F10=G10,1,0) -> 1 | I10: =(F10-G10)/G10*100 -> 0 | J10: 0.637 | K10: 0.023 | L10: 0.614 | M10: 0 | N10: 0 | O10: 0 | P10: 0 | Q10: 0 | R10: 0 | S10: 0 | T10: 0 | U10: 1 | W10: 4 | X10: =SUMPRODUCT((MOD(ROW(H152:H226),3)=1)*H152:H226) -> 24 | Y10: =SUMPRODUCT((MOD(ROW(I152:I226),3)=1)*I152:I226)/25 -> 0.078431373 | Z10: =SUMPRODUCT((MOD(ROW(J152:J226),3)=1)*J152:J226)/25 -> 212.07732 | AA10: =SUMPRODUCT((MOD(ROW(L152:L226),3)=1)*L152:L226)/25 -> 3.02368 | AB10: =SUMPRODUCT((MOD(ROW(M152:M226),3)=1)*M152:M226)/25 -> 0.52572 | AC10: =SUMPRODUCT((MOD(ROW(N152:N226),3)=1)*N152:N226)/25 -> 0.26676 | AD10: =SUMPRODUCT((MOD(ROW(P152:P226),3)=1)*P152:P226)/25 -> 2368.8 | AE10: =SUMPRODUCT((MOD(ROW(Q152:Q226),3)=1)*Q152:Q226)/25 -> 426.96 | AF10: =SUMPRODUCT((MOD(ROW(T152:T226),3)=1)*T152:T226)/25 -> 68.64
A11: 0 | B11: BM | C11: 0.2 | D11: 2 | E11: 4 | F11: 24 | G11: 24 | H11: =IF(F11=G11,1,0) -> 1 | I11: =(F11-G11)/G11*100 -> 0 | J11: 0.662 | K11: 0.026 | L11: 0.636 | M11: 0 | N11: 0 | O11: 0 | P11: 0 | Q11: 0 | R11: 0 | S11: 0 | T11: 0 | U11: 1 | W11: 2 | X11: =SUMPRODUCT((MOD(ROW(H227:H301),3)=2)*H227:H301) -> 24 | Y11: =SUMPRODUCT((MOD(ROW(I227:I301),3)=2)*I227:I301)/25 -> 0.18181818 | Z11: =SUMPRODUCT((MOD(ROW(J227:J301),3)=2)*J227:J301)/25 -> 144.93832 | AA11: =SUMPRODUCT((MOD(ROW(L227:L301),3)=2)*L227:L301)/25 -> 1.14596 | AB11: =SUMPRODUCT((MOD(ROW(M227:M301),3)=2)*M227:M301)/25 -> 2.14016 | AC11: =SUMPRODUCT((MOD(ROW(N227:N301),3)=2)*N227:N301)/25 -> 0.25984 | AD11: =SUMPRODUCT((MOD(ROW(P227:P301),3)=2)*P227:P301)/25 -> 1318.96 | AE11: =SUMPRODUCT((MOD(ROW(Q227:Q301),3)=2)*Q227:Q301)/25 -> 298.92 | AF11: =SUMPRODUCT((MOD(ROW(T227:T301),3)=2)*T227:T301)/25 -> 85.64
A12: 0 | B12: BM | C12: 0.2 | D12: 3 | E12: 4 | F12: 24 | G12: 24 | H12: =IF(F12=G12,1,0) -> 1 | I12: =(F12-G12)/G12*100 -> 0 | J12: 0.689 | K12: 0.026 | L12: 0.663 | M12: 0 | N12: 0 | O12: 0 | P12: 0 | Q12: 0 | R12: 0 | S12: 0 | T12: 0 | U12: 1 | W12: 3 | X12: =SUMPRODUCT((MOD(ROW(H227:H301),3)=0)*H227:H301) -> 23 | Y12: =SUMPRODUCT((MOD(ROW(I227:I301),3)=0)*I227:I301)/25 -> 0.36363636 | Z12: =SUMPRODUCT((MOD(ROW(J227:J301),3)=0)*J227:J301)/25 -> 289.11676 | AA12: =SUMPRODUCT((MOD(ROW(L227:L301),3)=0)*L227:L301)/25 -> 1.74996 | AB12: =SUMPRODUCT((MOD(ROW(M227:M301),3)=0)*M227:M301)/25 -> 7.22568 | AC12: =SUMPRODUCT((MOD(ROW(N227:N301),3)=0)*N227:N301)/25 -> 0.36064 | AD12: =SUMPRODUCT((MOD(ROW(P227:P301),3)=0)*P227:P301)/25 -> 3182.04 | AE12: =SUMPRODUCT((MOD(ROW(Q227:Q301),3)=0)*Q227:Q301)/25 -> 923.04 | AF12: =SUMPRODUCT((MOD(ROW(T227:T301),3)=0)*T227:T301)/25 -> 235.28
A13: 0 | B13: BM | C13: 0.2 | D13: 4 | E13: 4 | F13: 24 | G13: 24 | H13: =IF(F13=G13,1,0) -> 1 | I13: =(F13-G13)/G13*100 -> 0 | J13: 0.666 | K13: 0.026 | L13: 0.64 | M13: 0 | N13: 0 | O13: 0 | P13: 0 | Q13: 0 | R13: 0 | S13: 0 | T13: 0 | U13: 1 | W13: 4 | X13: =SUMPRODUCT((MOD(ROW(H227:H301),3)=1)*H227:H301) -> 22 | Y13: =SUMPRODUCT((MOD(ROW(I227:I301),3)=1)*I227:I301)/25 -> 0.70301357 | Z13: =SUMPRODUCT((MOD(ROW(J227:J301),3)=1)*J227:J301)/25 -> 433.0632 | AA13: =SUMPRODUCT((MOD(ROW(L227:L301),3)=1)*L227:L301)/25 -> 1.95764 | AB13: =SUMPRODUCT((MOD(ROW(M227:M301),3)=1)*M227:M301)/25 -> 2.28336 | AC13: =SUMPRODUCT((MOD(ROW(N227:N301),3)=1)*N227:N301)/25 -> 0.10584 | AD13: =SUMPRODUCT((MOD(ROW(P227:P301),3)=1)*P227:P301)/25 -> 2627.68 | AE13: =SUMPRODUCT((MOD(ROW(Q227:Q301),3)=1)*Q227:Q301)/25 -> 541 | AF13: =SUMPRODUCT((MOD(ROW(T227:T301),3)=1)*T227:T301)/25 -> 81.8
A14: 0 | B14: BM | C14: 0.2 | D14: 2 | E14: 5 | F14: 22 | G14: 22 | H14: =IF(F14=G14,1,0) -> 1 | I14: =(F14-G14)/G14*100 -> 0 | J14: 0.603 | K14: 0.023 | L14: 0.58 | M14: 0 | N14: 0 | O14: 0 | P14: 0 | Q14: 0 | R14: 0 | S14: 0 | T14: 0 | U14: 1 | W14: 2 | X14: =SUMPRODUCT((MOD(ROW(H302:H376),3)=2)*H302:H376) -> 25 | Y14: =SUMPRODUCT((MOD(ROW(I302:I376),3)=2)*I302:I376)/25 -> 0 | Z14: =SUMPRODUCT((MOD(ROW(J302:J376),3)=2)*J302:J376)/25 -> 0.62592 | AA14: =SUMPRODUCT((MOD(ROW(L302:L376),3)=2)*L302:L376)/25 -> 0.54228 | AB14: =SUMPRODUCT((MOD(ROW(M302:M376),3)=2)*M302:M376)/25 -> 0 | AC14: =SUMPRODUCT((MOD(ROW(N302:N376),3)=2)*N302:N376)/25 -> 0 | AD14: =SUMPRODUCT((MOD(ROW(P302:P376),3)=2)*P302:P376)/25 -> 0 | AE14: =SUMPRODUCT((MOD(ROW(Q302:Q376),3)=2)*Q302:Q376)/25 -> 0 | AF14: =SUMPRODUCT((MOD(ROW(T302:T376),3)=2)*T302:T376)/25 -> 0
A15: 0 | B15: BM | C15: 0.2 | D15: 3 | E15: 5 | F15: 22 | G15: 22 | H15: =IF(F15=G15,1,0) -> 1 | I15: =(F15-G15)/G15*100 -> 0 | J15: 0.63 | K15: 0.024 | L15: 0.606 | M15: 0 | N15: 0 | O15: 0 | P15: 0 | Q15: 0 | R15: 0 | S15: 0 | T15: 0 | U15: 1 | W15: 3 | X15: =SUMPRODUCT((MOD(ROW(H302:H376),3)=0)*H302:H376) -> 25 | Y15: =SUMPRODUCT((MOD(ROW(I302:I376),3)=0)*I302:I376)/25 -> 0 | Z15: =SUMPRODUCT((MOD(ROW(J302:J376),3)=0)*J302:J376)/25 -> 1.08844 | AA15: =SUMPRODUCT((MOD(ROW(L302:L376),3)=0)*L302:L376)/25 -> 1.00704 | AB15: =SUMPRODUCT((MOD(ROW(M302:M376),3)=0)*M302:M376)/25 -> 0 | AC15: =SUMPRODUCT((MOD(ROW(N302:N376),3)=0)*N302:N376)/25 -> 0 | AD15: =SUMPRODUCT((MOD(ROW(P302:P376),3)=0)*P302:P376)/25 -> 0 | AE15: =SUMPRODUCT((MOD(ROW(Q302:Q376),3)=0)*Q302:Q376)/25 -> 0 | AF15: =SUMPRODUCT((MOD(ROW(T302:T376),3)=0)*T302:T376)/25 -> 0
A16: 0 | B16: BM | C16: 0.2 | D16: 4 | E16: 5 | F16: 23 | G16: 23 | H16: =IF(F16=G16,1,0) -> 1 | I16: =(F16-G16)/G16*100 -> 0 | J16: 1.785 | K16: 0.018 | L16: 1.767 | M16: 0 | N16: 0 | O16: 0 | P16: 0 | Q16: 0 | R16: 0 | S16: 0 | T16: 0 | U16: 1 | W16: 4 | X16: =SUMPRODUCT((MOD(ROW(H302:H376),3)=1)*H302:H376) -> 25 | Y16: =SUMPRODUCT((MOD(ROW(I302:I376),3)=1)*I302:I376)/25 -> 0 | Z16: =SUMPRODUCT((MOD(ROW(J302:J376),3)=1)*J302:J376)/25 -> 2.58244 | AA16: =SUMPRODUCT((MOD(ROW(L302:L376),3)=1)*L302:L376)/25 -> 2.13544 | AB16: =SUMPRODUCT((MOD(ROW(M302:M376),3)=1)*M302:M376)/25 -> 0.00196 | AC16: =SUMPRODUCT((MOD(ROW(N302:N376),3)=1)*N302:N376)/25 -> 0.00016 | AD16: =SUMPRODUCT((MOD(ROW(P302:P376),3)=1)*P302:P376)/25 -> 71.12 | AE16: =SUMPRODUCT((MOD(ROW(Q302:Q376),3)=1)*Q302:Q376)/25 -> 0.2 | AF16: =SUMPRODUCT((MOD(ROW(T302:T376),3)=1)*T302:T376)/25 -> 0.12
A17: 0 | B17: BM | C17: 0.2 | D17: 2 | E17: 6 | F17: 22 | G17: 22 | H17: =IF(F17=G17,1,0) -> 1 | I17: =(F17-G17)/G17*100 -> 0 | J17: 0.738 | K17: 0.025 | L17: 0.713 | M17: 0 | N17: 0 | O17: 0 | P17: 0 | Q17: 0 | R17: 0 | S17: 0 | T17: 0 | U17: 1 | W17: 2 | X17: =SUMPRODUCT((MOD(ROW(H377:H451),3)=2)*H377:H451) -> 23 | Y17: =SUMPRODUCT((MOD(ROW(I377:I451),3)=2)*I377:I451)/25 -> 0.15535445 | Z17: =SUMPRODUCT((MOD(ROW(J377:J451),3)=2)*J377:J451)/25 -> 294.73324 | AA17: =SUMPRODUCT((MOD(ROW(L377:L451),3)=2)*L377:L451)/25 -> 2.56904 | AB17: =SUMPRODUCT((MOD(ROW(M377:M451),3)=2)*M377:M451)/25 -> 0.11696 | AC17: =SUMPRODUCT((MOD(ROW(N377:N451),3)=2)*N377:N451)/25 -> 0.14688 | AD17: =SUMPRODUCT((MOD(ROW(P377:P451),3)=2)*P377:P451)/25 -> 1064.76 | AE17: =SUMPRODUCT((MOD(ROW(Q377:Q451),3)=2)*Q377:Q451)/25 -> 234.6 | AF17: =SUMPRODUCT((MOD(ROW(T377:T451),3)=2)*T377:T451)/25 -> 60.2
A18: 0 | B18: BM | C18: 0.2 | D18: 3 | E18: 6 | F18: 22 | G18: 22 | H18: =IF(F18=G18,1,0) -> 1 | I18: =(F18-G18)/G18*100 -> 0 | J18: 0.785 | K18: 0.024 | L18: 0.761 | M18: 0 | N18: 0 | O18: 0 | P18: 0 | Q18: 0 | R18: 0 | S18: 0 | T18: 0 | U18: 1 | W18: 3 | X18: =SUMPRODUCT((MOD(ROW(H377:H451),3)=0)*H377:H451) -> 23 | Y18: =SUMPRODUCT((MOD(ROW(I377:I451),3)=0)*I377:I451)/25 -> 0.15250545 | Z18: =SUMPRODUCT((MOD(ROW(J377:J451),3)=0)*J377:J451)/25 -> 290.92688 | AA18: =SUMPRODUCT((MOD(ROW(L377:L451),3)=0)*L377:L451)/25 -> 3.24352 | AB18: =SUMPRODUCT((MOD(ROW(M377:M451),3)=0)*M377:M451)/25 -> 0.278 | AC18: =SUMPRODUCT((MOD(ROW(N377:N451),3)=0)*N377:N451)/25 -> 0.28652 | AD18: =SUMPRODUCT((MOD(ROW(P377:P451),3)=0)*P377:P451)/25 -> 1118.28 | AE18: =SUMPRODUCT((MOD(ROW(Q377:Q451),3)=0)*Q377:Q451)/25 -> 415.12 | AF18: =SUMPRODUCT((MOD(ROW(T377:T451),3)=0)*T377:T451)/25 -> 155.8
A19: 0 | B19: BM | C19: 0.2 | D19: 4 | E19: 6 | F19: 22 | G19: 22 | H19: =IF(F19=G19,1,0) -> 1 | I19: =(F19-G19)/G19*100 -> 0 | J19: 0.779 | K19: 0.024 | L19: 0.755 | M19: 0 | N19: 0 | O19: 0 | P19: 0 | Q19: 0 | R19: 0 | S19: 0 | T19: 0 | U19: 1 | W19: 4 | X19: =SUMPRODUCT((MOD(ROW(H377:H451),3)=1)*H377:H451) -> 23 | Y19: =SUMPRODUCT((MOD(ROW(I377:I451),3)=1)*I377:I451)/25 -> 0.15115865 | Z19: =SUMPRODUCT((MOD(ROW(J377:J451),3)=1)*J377:J451)/25 -> 313.05228 | AA19: =SUMPRODUCT((MOD(ROW(L377:L451),3)=1)*L377:L451)/25 -> 4.245 | AB19: =SUMPRODUCT((MOD(ROW(M377:M451),3)=1)*M377:M451)/25 -> 0.33644 | AC19: =SUMPRODUCT((MOD(ROW(N377:N451),3)=1)*N377:N451)/25 -> 0.44144 | AD19: =SUMPRODUCT((MOD(ROW(P377:P451),3)=1)*P377:P451)/25 -> 1520.64 | AE19: =SUMPRODUCT((MOD(ROW(Q377:Q451),3)=1)*Q377:Q451)/25 -> 1566.72 | AF19: =SUMPRODUCT((MOD(ROW(T377:T451),3)=1)*T377:T451)/25 -> 197.96
